Workbook

Sheet ENTRADA
B1: ÍNDICE DE VOLUME DE VENDAS NO VAREJO - BRASIL (Base: MÉDIA 2022=100)
B3: DADOS ORIGINAIS | S3: DADOS DESSAZONALIZADOS (2022 = 100)
A4: Período | B4: Comércio Varejista | C4: 1. Combustiveis e Lubrificantes | D4: 2. Hipermercados | F4: 3. Tecidos, vestuario e calçados | G4: 4. Moveis e Eletrodómesticos | J4: Demais artigos de uso pessoal e doméstico | N4: 9. Veículos, motos, partes e peças | O4: 10. Material de Construção | P4: 11. Atacado especializado em produtos alimenticios, bebidas e fumo | Q4: Comércio Varejista Ampliado | S4: Comércio Varejista | T4: 1. Combustiveis e Lubrificantes | U4: 2. Hipermercados | W4: 3. Tecidos, vestuario e calçados | X4: 4. Móveis e eletrodomésticos | Y4: Móveis | Z4: Eletrodomésticos | AA4: Demais artigos de uso pessoal e doméstico | AE4: 9. Veículos, motos, partes e peças | AF4: 10. Material de Construção | AG4: 11. Atacado especializado em produtos alimenticios, bebidas e fumo | AH4: Comércio Varejista Ampliado
D5: Total | E5: 2.1 Supermercados e Hipermercados | G5: Total | H5: Móveis | I5: Eletrodomésticos | J5: 5. Artigos farmaceuticos, médicos, ortopédicos, de perfumaria e cosméticos | K5: 6. Livros Jornais, revistas e papelaria | L5: 7. Equipamentos e materiais para escritório, informática e comunicação | M5: 8. Outros artigos de uso pessoal e domésticos | U5: Total | V5: 2.1 Supermercados e Hipermercados | AA5: 5. Artigos farmaceuticos, médicos, ortopédicos, de perfumaria e cosméticos | AB5: 6. Livros Jornais, revistas e papelaria | AC5: 7. Equipamentos e materiais para escritório, informática e comunicação | AD5: 8. Outros artigos de uso pessoal e domésticos
A6: 36526 | B6: ='[1]Tabela 1'!B6 -> 46.56262 | C6: ='[2]Tabela 1'!B7 -> 95.86755 | D6: ='[2]Tabela 1'!C7 -> 52.56897 | E6: ='[2]Tabela 1'!D7 -> 50.64794 | F6: ='[2]Tabela 1'!E7 -> 61.98629 | G6: ='[2]Tabela 1'!F7 -> 30.85988 | H6: ='[2]Tabela 1'!G7 -> - | I6: ='[2]Tabela 1'!H7 -> - | J6: ='[2]Tabela 1'!I7 -> - | ... P6: ='[2]Tabela 1'!O7 -> - | Q6: ='[3]Tabela 1'!#REF! -> #REF! | R6: =B6-S6 -> -3.59125 | S6: ='[1]Tabela 2'!B6 -> 50.15387 | T6: ='[2]Tabela 2'!B7 -> 98.67715 | U6: ='[2]Tabela 2'!C7 -> 54.72077 | V6: ='[2]Tabela 2'!D7 -> 52.86533 | W6: ='[2]Tabela 2'!E7 -> 84.7153 | X6: ='[2]Tabela 2'!F7 -> 32.99758 | Y6: ='[2]Tabela 2'!G7 -> - | Z6: ='[2]Tabela 2'!H7 -> - | AA6: ='[2]Tabela 2'!I7 -> - | ... AG6: ='[2]Tabela 2'!O7 -> - | AH6: ='[3]Tabela 2'!#REF! -> #REF!
A7: =EDATE(A6,1) -> 36557 | B7: ='[1]Tabela 1'!B7 -> 47.08777 | C7: ='[2]Tabela 1'!B8 -> 93.80588 | D7: ='[2]Tabela 1'!C8 -> 52.22312 | E7: ='[2]Tabela 1'!D8 -> 50.22728 | F7: ='[2]Tabela 1'!E8 -> 67.813 | G7: ='[2]Tabela 1'!F8 -> 29.70918 | H7: ='[2]Tabela 1'!G8 -> - | I7: ='[2]Tabela 1'!H8 -> - | J7: ='[2]Tabela 1'!I8 -> - | ... P7: ='[2]Tabela 1'!O8 -> - | Q7: ='[3]Tabela 1'!#REF! -> #REF! | R7: =B7-S7 -> -3.51407 | S7: ='[1]Tabela 2'!B7 -> 50.60184 | T7: ='[2]Tabela 2'!B8 -> 98.02877 | U7: ='[2]Tabela 2'!C8 -> 55.28715 | V7: ='[2]Tabela 2'!D8 -> 53.2079 | W7: ='[2]Tabela 2'!E8 -> 86.07801 | X7: ='[2]Tabela 2'!F8 -> 34.06676 | Y7: ='[2]Tabela 2'!G8 -> - | Z7: ='[2]Tabela 2'!H8 -> - | AA7: ='[2]Tabela 2'!I8 -> - | ... AG7: ='[2]Tabela 2'!O8 -> - | AH7: ='[3]Tabela 2'!#REF! -> #REF!
A8: =EDATE(A7,1) -> 36586 | B8: ='[1]Tabela 1'!B8 -> 49.10081 | C8: ='[2]Tabela 1'!B9 -> 96.69222 | D8: ='[2]Tabela 1'!C9 -> 55.42222 | E8: ='[2]Tabela 1'!D9 -> 53.59259 | F8: ='[2]Tabela 1'!E9 -> 71.28423 | G8: ='[2]Tabela 1'!F9 -> 31.48754 | H8: ='[2]Tabela 1'!G9 -> - | I8: ='[2]Tabela 1'!H9 -> - | J8: ='[2]Tabela 1'!I9 -> - | ... P8: ='[2]Tabela 1'!O9 -> - | Q8: ='[3]Tabela 1'!#REF! -> #REF! | R8: =B8-S8 -> -1.81354 | S8: ='[1]Tabela 2'!B8 -> 50.91435 | T8: ='[2]Tabela 2'!B9 -> 97.53394 | U8: ='[2]Tabela 2'!C9 -> 55.35327 | V8: ='[2]Tabela 2'!D9 -> 53.47435 | W8: ='[2]Tabela 2'!E9 -> 87.83695 | X8: ='[2]Tabela 2'!F9 -> 34.42562 | Y8: ='[2]Tabela 2'!G9 -> - | Z8: ='[2]Tabela 2'!H9 -> - | AA8: ='[2]Tabela 2'!I9 -> - | ... AG8: ='[2]Tabela 2'!O9 -> - | AH8: ='[3]Tabela 2'!#REF! -> #REF!
A9: =EDATE(A8,1) -> 36617 | B9: ='[1]Tabela 1'!B9 -> 49.10081 | C9: ='[2]Tabela 1'!B10 -> 96.27988 | D9: ='[2]Tabela 1'!C10 -> 56.45977 | E9: ='[2]Tabela 1'!D10 -> 54.60218 | F9: ='[2]Tabela 1'!E10 -> 78.2267 | G9: ='[2]Tabela 1'!F10 -> 30.12761 | H9: ='[2]Tabela 1'!G10 -> - | I9: ='[2]Tabela 1'!H10 -> - | J9: ='[2]Tabela 1'!I10 -> - | ... P9: ='[2]Tabela 1'!O10 -> - | Q9: ='[3]Tabela 1'!#REF! -> #REF! | R9: =B9-S9 -> -1.86325 | S9: ='[1]Tabela 2'!B9 -> 50.96406 | T9: ='[2]Tabela 2'!B10 -> 97.87454 | U9: ='[2]Tabela 2'!C10 -> 55.38913 | V9: ='[2]Tabela 2'!D10 -> 53.70747 | W9: ='[2]Tabela 2'!E10 -> 89.31395 | X9: ='[2]Tabela 2'!F10 -> 34.23967 | Y9: ='[2]Tabela 2'!G10 -> - | Z9: ='[2]Tabela 2'!H10 -> - | AA9: ='[2]Tabela 2'!I10 -> - | ... AG9: ='[2]Tabela 2'!O10 -> - | AH9: ='[3]Tabela 2'!#REF! -> #REF!
A10: =EDATE(A9,1) -> 36647 | B10: ='[1]Tabela 1'!B10 -> 51.11386 | C10: ='[2]Tabela 1'!B11 -> 95.5583 | D10: ='[2]Tabela 1'!C11 -> 54.03883 | E10: ='[2]Tabela 1'!D11 -> 52.16233 | F10: ='[2]Tabela 1'!E11 -> 96.57464 | G10: ='[2]Tabela 1'!F11 -> 36.4042 | H10: ='[2]Tabela 1'!G11 -> - | I10: ='[2]Tabela 1'!H11 -> - | J10: ='[2]Tabela 1'!I11 -> - | ... P10: ='[2]Tabela 1'!O11 -> - | Q10: ='[3]Tabela 1'!#REF! -> #REF! | R10: =B10-S10 -> -0.1588 | S10: ='[1]Tabela 2'!B10 -> 51.27266 | T10: ='[2]Tabela 2'!B11 -> 95.24986 | U10: ='[2]Tabela 2'!C11 -> 55.83733 | V10: ='[2]Tabela 2'!D11 -> 54.05211 | W10: ='[2]Tabela 2'!E11 -> 87.79416 | X10: ='[2]Tabela 2'!F11 -> 35.06499 | Y10: ='[2]Tabela 2'!G11 -> - | Z10: ='[2]Tabela 2'!H11 -> - | AA10: ='[2]Tabela 2'!I11 -> - | ... AG10: ='[2]Tabela 2'!O11 -> - | AH10: ='[3]Tabela 2'!#REF! -> #REF!
A11: =EDATE(A10,1) -> 36678 | B11: ='[1]Tabela 1'!B11 -> 48.66319 | C11: ='[2]Tabela 1'!B12 -> 95.35213 | D11: ='[2]Tabela 1'!C12 -> 54.03883 | E11: ='[2]Tabela 1'!D12 -> 52.24647 | F11: ='[2]Tabela 1'!E12 -> 90.49998 | G11: ='[2]Tabela 1'!F12 -> 31.90598 | H11: ='[2]Tabela 1'!G12 -> - | I11: ='[2]Tabela 1'!H12 -> - | J11: ='[2]Tabela 1'!I12 -> - | ... P11: ='[2]Tabela 1'!O12 -> - | Q11: ='[3]Tabela 1'!#REF! -> #REF! | R11: =B11-S11 -> -2.4863 | S11: ='[1]Tabela 2'!B11 -> 51.14949 | T11: ='[2]Tabela 2'!B12 -> 95.0608 | U11: ='[2]Tabela 2'!C12 -> 56.78279 | V11: ='[2]Tabela 2'!D12 -> 54.86354 | W11: ='[2]Tabela 2'!E12 -> 88.50167 | X11: ='[2]Tabela 2'!F12 -> 35.66516 | Y11: ='[2]Tabela 2'!G12 -> - | Z11: ='[2]Tabela 2'!H12 -> - | AA11: ='[2]Tabela 2'!I12 -> - | ... AG11: ='[2]Tabela 2'!O12 -> - | AH11: ='[3]Tabela 2'!#REF! -> #REF!
A12: =EDATE(A11,1) -> 36708 | B12: ='[1]Tabela 1'!B12 -> 50.41367 | C12: ='[2]Tabela 1'!B13 -> 95.97063 | D12: ='[2]Tabela 1'!C13 -> 56.02746 | E12: ='[2]Tabela 1'!D13 -> 54.34979 | F12: ='[2]Tabela 1'!E13 -> 88.39245 | G12: ='[2]Tabela 1'!F13 -> 35.14888 | H12: ='[2]Tabela 1'!G13 -> - | I12: ='[2]Tabela 1'!H13 -> - | J12: ='[2]Tabela 1'!I13 -> - | ... P12: ='[2]Tabela 1'!O13 -> - | Q12: ='[3]Tabela 1'!#REF! -> #REF! | R12: =B12-S12 -> -0.89441 | S12: ='[1]Tabela 2'!B12 -> 51.30808 | T12: ='[2]Tabela 2'!B13 -> 93.07969 | U12: ='[2]Tabela 2'!C13 -> 56.68183 | V12: ='[2]Tabela 2'!D13 -> 54.88491 | W12: ='[2]Tabela 2'!E13 -> 88.51483 | X12: ='[2]Tabela 2'!F13 -> 36.35703 | Y12: ='[2]Tabela 2'!G13 -> - | Z12: ='[2]Tabela 2'!H13 -> - | AA12: ='[2]Tabela 2'!I13 -> - | ... AG12: ='[2]Tabela 2'!O13 -> - | AH12: ='[3]Tabela 2'!#REF! -> #REF!
A13: =EDATE(A12,1) -> 36739 | B13: ='[1]Tabela 1'!B13 -> 50.23862 | C13: ='[2]Tabela 1'!B14 -> 91.53805 | D13: ='[2]Tabela 1'!C14 -> 55.33576 | E13: ='[2]Tabela 1'!D14 -> 53.59259 | F13: ='[2]Tabela 1'!E14 -> 82.81368 | G13: ='[2]Tabela 1'!F14 -> 36.29959 | H13: ='[2]Tabela 1'!G14 -> - | I13: ='[2]Tabela 1'!H14 -> - | J13: ='[2]Tabela 1'!I14 -> - | ... P13: ='[2]Tabela 1'!O14 -> - | Q13: ='[3]Tabela 1'!#REF! -> #REF! | R13: =B13-S13 -> -0.64961 | S13: ='[1]Tabela 2'!B13 -> 50.88823 | T13: ='[2]Tabela 2'!B14 -> 88.3401 | U13: ='[2]Tabela 2'!C14 -> 56.41067 | V13: ='[2]Tabela 2'!D14 -> 54.57317 | W13: ='[2]Tabela 2'!E14 -> 87.33571 | X13: ='[2]Tabela 2'!F14 -> 36.84836 | Y13: ='[2]Tabela 2'!G14 -> - | Z13: ='[2]Tabela 2'!H14 -> - | AA13: ='[2]Tabela 2'!I14 -> - | ... AG13: ='[2]Tabela 2'!O14 -> - | AH13: ='[3]Tabela 2'!#REF! -> #REF!
A14: =EDATE(A13,1) -> 36770 | B14: ='[1]Tabela 1'!B14 -> 49.01329 | C14: ='[2]Tabela 1'!B15 -> 90.50721 | D14: ='[2]Tabela 1'!C15 -> 55.59515 | E14: ='[2]Tabela 1'!D15 -> 54.01326 | F14: ='[2]Tabela 1'!E15 -> 75.00341 | G14: ='[2]Tabela 1'!F15 -> 33.68435 | H14: ='[2]Tabela 1'!G15 -> - | I14: ='[2]Tabela 1'!H15 -> - | J14: ='[2]Tabela 1'!I15 -> - | ... P14: ='[2]Tabela 1'!O15 -> - | Q14: ='[3]Tabela 1'!#REF! -> #REF! | R14: =B14-S14 -> -1.95548 | S14: ='[1]Tabela 2'!B14 -> 50.96877 | T14: ='[2]Tabela 2'!B15 -> 90.20495 | U14: ='[2]Tabela 2'!C15 -> 56.80326 | V14: ='[2]Tabela 2'!D15 -> 55.02685 | W14: ='[2]Tabela 2'!E15 -> 88.13881 | X14: ='[2]Tabela 2'!F15 -> 36.66248 | Y14: ='[2]Tabela 2'!G15 -> - | Z14: ='[2]Tabela 2'!H15 -> - | AA14: ='[2]Tabela 2'!I15 -> - | ... AG14: ='[2]Tabela 2'!O15 -> - | AH14: ='[3]Tabela 2'!#REF! -> #REF!
A15: =EDATE(A14,1) -> 36800 | B15: ='[1]Tabela 1'!B15 -> 49.97605 | C15: ='[2]Tabela 1'!B16 -> 93.0843 | D15: ='[2]Tabela 1'!C16 -> 54.98991 | E15: ='[2]Tabela 1'!D16 -> 53.25606 | F15: ='[2]Tabela 1'!E16 -> 78.35067 | G15: ='[2]Tabela 1'!F16 -> 35.56732 | H15: ='[2]Tabela 1'!G16 -> - | I15: ='[2]Tabela 1'!H16 -> - | J15: ='[2]Tabela 1'!I16 -> - | ... P15: ='[2]Tabela 1'!O16 -> - | Q15: ='[3]Tabela 1'!#REF! -> #REF! | R15: =B15-S15 -> -0.26393 | S15: ='[1]Tabela 2'!B15 -> 50.23998 | T15: ='[2]Tabela 2'!B16 -> 90.43662 | U15: ='[2]Tabela 2'!C16 -> 55.68626 | V15: ='[2]Tabela 2'!D16 -> 54.13137 | W15: ='[2]Tabela 2'!E16 -> 84.99965 | X15: ='[2]Tabela 2'!F16 -> 35.27007 | Y15: ='[2]Tabela 2'!G16 -> - | Z15: ='[2]Tabela 2'!H16 -> - | AA15: ='[2]Tabela 2'!I16 -> - | ... AG15: ='[2]Tabela 2'!O16 -> - | AH15: ='[3]Tabela 2'!#REF! -> #REF!
A16: =EDATE(A15,1) -> 36831 | B16: ='[1]Tabela 1'!B16 -> 50.85129 | C16: ='[2]Tabela 1'!B17 -> 88.44555 | D16: ='[2]Tabela 1'!C17 -> 55.2493 | E16: ='[2]Tabela 1'!D17 -> 53.34019 | F16: ='[2]Tabela 1'!E17 -> 89.5082 | G16: ='[2]Tabela 1'!F17 -> 37.76413 | H16: ='[2]Tabela 1'!G17 -> - | I16: ='[2]Tabela 1'!H17 -> - | J16: ='[2]Tabela 1'!I17 -> - | ... P16: ='[2]Tabela 1'!O17 -> - | Q16: ='[3]Tabela 1'!#REF! -> #REF! | R16: =B16-S16 -> -0.24197 | S16: ='[1]Tabela 2'!B16 -> 51.09326 | T16: ='[2]Tabela 2'!B17 -> 89.8629 | U16: ='[2]Tabela 2'!C17 -> 56.44132 | V16: ='[2]Tabela 2'!D17 -> 54.60614 | W16: ='[2]Tabela 2'!E17 -> 87.40443 | X16: ='[2]Tabela 2'!F17 -> 36.96636 | Y16: ='[2]Tabela 2'!G17 -> - | Z16: ='[2]Tabela 2'!H17 -> - | AA16: ='[2]Tabela 2'!I17 -> - | ... AG16: ='[2]Tabela 2'!O17 -> - | AH16: ='[3]Tabela 2'!#REF! -> #REF!
A17: =EDATE(A16,1) -> 36861 | B17: ='[1]Tabela 1'!B17 -> 70.10651 | C17: ='[2]Tabela 1'!B18 -> 93.29047 | D17: ='[2]Tabela 1'!C18 -> 73.23342 | E17: ='[2]Tabela 1'!D18 -> 71.26048 | F17: ='[2]Tabela 1'!E18 -> 167.36298 | G17: ='[2]Tabela 1'!F18 -> 57.63998 | H17: ='[2]Tabela 1'!G18 -> - | I17: ='[2]Tabela 1'!H18 -> - | J17: ='[2]Tabela 1'!I18 -> - | ... P17: ='[2]Tabela 1'!O18 -> - | Q17: ='[3]Tabela 1'!#REF! -> #REF! | R17: =B17-S17 -> 18.88579 | S17: ='[1]Tabela 2'!B17 -> 51.22072 | T17: ='[2]Tabela 2'!B18 -> 90.2267 | U17: ='[2]Tabela 2'!C18 -> 57.25036 | V17: ='[2]Tabela 2'!D18 -> 55.41866 | W17: ='[2]Tabela 2'!E18 -> 86.79607 | X17: ='[2]Tabela 2'!F18 -> 36.90699 | Y17: ='[2]Tabela 2'!G18 -> - | Z17: ='[2]Tabela 2'!H18 -> - | AA17: ='[2]Tabela 2'!I18 -> - | ... AG17: ='[2]Tabela 2'!O18 -> - | AH17: ='[3]Tabela 2'!#REF! -> #REF!
A18: =EDATE(A17,1) -> 36892 | B18: ='[1]Tabela 1'!B18 -> 47.43786 | C18: ='[2]Tabela 1'!B19 -> 88.23938 | D18: ='[2]Tabela 1'!C19 -> 54.29822 | E18: ='[2]Tabela 1'!D19 -> 52.3306 | F18: ='[2]Tabela 1'!E19 -> 66.94519 | G18: ='[2]Tabela 1'!F19 -> 34.31201 | H18: ='[2]Tabela 1'!G19 -> - | I18: ='[2]Tabela 1'!H19 -> - | J18: ='[2]Tabela 1'!I19 -> - | ... P18: ='[2]Tabela 1'!O19 -> - | Q18: ='[3]Tabela 1'!#REF! -> #REF! | R18: =B18-S18 -> -3.67257 | S18: ='[1]Tabela 2'!B18 -> 51.11043 | T18: ='[2]Tabela 2'!B19 -> 90.90349 | U18: ='[2]Tabela 2'!C19 -> 57.45481 | V18: ='[2]Tabela 2'!D19 -> 55.47098 | W18: ='[2]Tabela 2'!E19 -> 88.98385 | X18: ='[2]Tabela 2'!F19 -> 36.66318 | Y18: ='[2]Tabela 2'!G19 -> - | Z18: ='[2]Tabela 2'!H19 -> - | AA18: ='[2]Tabela 2'!I19 -> - | ... AG18: ='[2]Tabela 2'!O19 -> - | AH18: ='[3]Tabela 2'!#REF! -> #REF!
... A36: =EDATE(A35,1) -> 37438 | B36: ='[1]Tabela 1'!B36 -> 49.18834 | C36: ='[2]Tabela 1'!B37 -> 100.71247 | D36: ='[2]Tabela 1'!C37 -> 54.29822 | E36: ='[2]Tabela 1'!D37 -> 53.17193 | F36: ='[2]Tabela 1'!E37 -> 87.64861 | G36: ='[2]Tabela 1'!F37 -> 33.26591 | H36: ='[2]Tabela 1'!G37 -> - | I36: ='[2]Tabela 1'!H37 -> - | J36: ='[2]Tabela 1'!I37 -> - | ... P36: ='[2]Tabela 1'!O37 -> - | Q36: ='[3]Tabela 1'!#REF! -> #REF! | R36: =B36-S36 -> -0.93276 | S36: ='[1]Tabela 2'!B36 -> 50.1211 | T36: ='[2]Tabela 2'!B37 -> 97.11348 | U36: ='[2]Tabela 2'!C37 -> 55.80746 | V36: ='[2]Tabela 2'!D37 -> 54.58173 | W36: ='[2]Tabela 2'!E37 -> 88.06197 | X36: ='[2]Tabela 2'!F37 -> 34.23746 | Y36: ='[2]Tabela 2'!G37 -> - | Z36: ='[2]Tabela 2'!H37 -> - | AA36: ='[2]Tabela 2'!I37 -> - | ... AG36: ='[2]Tabela 2'!O37 -> - | AH36: ='[3]Tabela 2'!#REF! -> #REF!
A37: =EDATE(A36,1) -> 37469 | B37: ='[1]Tabela 1'!B37 -> 50.76376 | C37: ='[2]Tabela 1'!B38 -> 105.14505 | D37: ='[2]Tabela 1'!C38 -> 56.20038 | E37: ='[2]Tabela 1'!D38 -> 55.10698 | F37: ='[2]Tabela 1'!E38 -> 87.64861 | G37: ='[2]Tabela 1'!F38 -> 34.10279 | H37: ='[2]Tabela 1'!G38 -> - | I37: ='[2]Tabela 1'!H38 -> - | J37: ='[2]Tabela 1'!I38 -> - | ... P37: ='[2]Tabela 1'!O38 -> - | Q37: ='[3]Tabela 1'!B1 -> 0 | R37: =B37-S37 -> 0.24272 | S37: ='[1]Tabela 2'!B37 -> 50.52104 | T37: ='[2]Tabela 2'!B38 -> 101.23114 | U37: ='[2]Tabela 2'!C38 -> 55.84355 | V37: ='[2]Tabela 2'!D38 -> 54.63526 | W37: ='[2]Tabela 2'!E38 -> 92.15607 | X37: ='[2]Tabela 2'!F38 -> 34.75101 | Y37: ='[2]Tabela 2'!G38 -> - | Z37: ='[2]Tabela 2'!H38 -> - | AA37: ='[2]Tabela 2'!I38 -> - | ... AG37: ='[2]Tabela 2'!O38 -> - | AH37: ='[3]Tabela 2'!B1 -> 0
A38: =EDATE(A37,1) -> 37500 | B38: ='[1]Tabela 1'!B38 -> 46.91272 | C38: ='[2]Tabela 1'!B39 -> 101.1248 | D38: ='[2]Tabela 1'!C39 -> 51.96374 | E38: ='[2]Tabela 1'!D39 -> 50.81621 | F38: ='[2]Tabela 1'!E39 -> 75.25136 | G38: ='[2]Tabela 1'!F39 -> 31.27832 | H38: ='[2]Tabela 1'!G39 -> - | I38: ='[2]Tabela 1'!H39 -> - | J38: ='[2]Tabela 1'!I39 -> - | ... P38: ='[2]Tabela 1'!O39 -> - | Q38: ='[3]Tabela 1'!B2 -> 0 | R38: =B38-S38 -> -3.01937 | S38: ='[1]Tabela 2'!B38 -> 49.93209 | T38: ='[2]Tabela 2'!B39 -> 101.41751 | U38: ='[2]Tabela 2'!C39 -> 54.68025 | V38: ='[2]Tabela 2'!D39 -> 53.5068 | W38: ='[2]Tabela 2'!E39 -> 88.71215 | X38: ='[2]Tabela 2'!F39 -> 33.99122 | Y38: ='[2]Tabela 2'!G39 -> - | Z38: ='[2]Tabela 2'!H39 -> - | AA38: ='[2]Tabela 2'!I39 -> - | ... AG38: ='[2]Tabela 2'!O39 -> - | AH38: ='[3]Tabela 2'!B2 -> 0
A39: =EDATE(A38,1) -> 37530 | B39: ='[1]Tabela 1'!B39 -> 50.85129 | C39: ='[2]Tabela 1'!B40 -> 102.46489 | D39: ='[2]Tabela 1'!C40 -> 55.68161 | E39: ='[2]Tabela 1'!D40 -> 54.43392 | F39: ='[2]Tabela 1'!E40 -> 84.42533 | G39: ='[2]Tabela 1'!F40 -> 35.25349 | H39: ='[2]Tabela 1'!G40 -> - | I39: ='[2]Tabela 1'!H40 -> - | J39: ='[2]Tabela 1'!I40 -> - | ... P39: ='[2]Tabela 1'!O40 -> - | Q39: ='[3]Tabela 1'!B3 -> 0 | R39: =B39-S39 -> 0.50776 | S39: ='[1]Tabela 2'!B39 -> 50.34353 | T39: ='[2]Tabela 2'!B40 -> 98.27458 | U39: ='[2]Tabela 2'!C40 -> 55.58356 | V39: ='[2]Tabela 2'!D40 -> 54.45351 | W39: ='[2]Tabela 2'!E40 -> 89.49299 | X39: ='[2]Tabela 2'!F40 -> 35.02899 | Y39: ='[2]Tabela 2'!G40 -> - | Z39: ='[2]Tabela 2'!H40 -> - | AA39: ='[2]Tabela 2'!I40 -> - | ... AG39: ='[2]Tabela 2'!O40 -> - | AH39: ='[3]Tabela 2'!B3 -> 0
A40: =EDATE(A39,1) -> 37561 | B40: ='[1]Tabela 1'!B40 -> 49.62596 | C40: ='[2]Tabela 1'!B41 -> 94.3213 | D40: ='[2]Tabela 1'!C41 -> 54.47114 | E40: ='[2]Tabela 1'!D41 -> 53.34019 | F40: ='[2]Tabela 1'!E41 -> 90.99587 | G40: ='[2]Tabela 1'!F41 -> 34.62583 | H40: ='[2]Tabela 1'!G41 -> - | I40: ='[2]Tabela 1'!H41 -> - | J40: ='[2]Tabela 1'!I41 -> - | ... P40: ='[2]Tabela 1'!O41 -> - | Q40: ='[3]Tabela 1'!B4 -> 0 | R40: =B40-S40 -> 0.41957 | S40: ='[1]Tabela 2'!B40 -> 49.20639 | T40: ='[2]Tabela 2'!B41 -> 95.33611 | U40: ='[2]Tabela 2'!C41 -> 54.45705 | V40: ='[2]Tabela 2'!D41 -> 53.32291 | W40: ='[2]Tabela 2'!E41 -> 89.46439 | X40: ='[2]Tabela 2'!F41 -> 34.02306 | Y40: ='[2]Tabela 2'!G41 -> - | Z40: ='[2]Tabela 2'!H41 -> - | AA40: ='[2]Tabela 2'!I41 -> - | ... AG40: ='[2]Tabela 2'!O41 -> - | AH40: ='[3]Tabela 2'!B4 -> 0
A41: =EDATE(A40,1) -> 37591 | B41: ='[1]Tabela 1'!B41 -> 64.68004 | C41: ='[2]Tabela 1'!B42 -> 97.72305 | D41: ='[2]Tabela 1'!C42 -> 65.53829 | E41: ='[2]Tabela 1'!D42 -> 64.61399 | F41: ='[2]Tabela 1'!E42 -> 167.23901 | G41: ='[2]Tabela 1'!F42 -> 50.52652 | H41: ='[2]Tabela 1'!G42 -> - | I41: ='[2]Tabela 1'!H42 -> - | J41: ='[2]Tabela 1'!I42 -> - | ... P41: ='[2]Tabela 1'!O42 -> - | Q41: ='[3]Tabela 1'!B5 -> 0 | R41: =B41-S41 -> 16.46228 | S41: ='[1]Tabela 2'!B41 -> 48.21776 | T41: ='[2]Tabela 2'!B42 -> 94.30028 | U41: ='[2]Tabela 2'!C42 -> 52.87487 | V41: ='[2]Tabela 2'!D42 -> 51.92463 | W41: ='[2]Tabela 2'!E42 -> 83.59985 | X41: ='[2]Tabela 2'!F42 -> 32.58177 | Y41: ='[2]Tabela 2'!G42 -> - | Z41: ='[2]Tabela 2'!H42 -> - | AA41: ='[2]Tabela 2'!I42 -> - | ... AG41: ='[2]Tabela 2'!O42 -> - | AH41: ='[3]Tabela 2'!B5 -> 0
A42: =EDATE(A41,1) -> 37622 | B42: ='[1]Tabela 1'!B42 -> 44.81215 | C42: ='[2]Tabela 1'!B43 -> 88.23938 | D42: ='[2]Tabela 1'!C43 -> 50.83973 | E42: ='[2]Tabela 1'!D43 -> 49.97488 | F42: ='[2]Tabela 1'!E43 -> 66.4493 | G42: ='[2]Tabela 1'!F43 -> 30.85988 | H42: ='[2]Tabela 1'!G43 -> - | I42: ='[2]Tabela 1'!H43 -> - | J42: ='[2]Tabela 1'!I43 -> 24.87825 | ... P42: ='[2]Tabela 1'!O43 -> - | Q42: ='[3]Tabela 1'!B6 -> 45.76243 | R42: =B42-S42 -> -2.96814 | S42: ='[1]Tabela 2'!B42 -> 47.78029 | T42: ='[2]Tabela 2'!B43 -> 90.22299 | U42: ='[2]Tabela 2'!C43 -> 52.89676 | V42: ='[2]Tabela 2'!D43 -> 52.05325 | W42: ='[2]Tabela 2'!E43 -> 87.47571 | X42: ='[2]Tabela 2'!F43 -> 32.90178 | Y42: ='[2]Tabela 2'!G43 -> - | Z42: ='[2]Tabela 2'!H43 -> - | AA42: ='[2]Tabela 2'!I43 -> 25.54661 | ... AG42: ='[2]Tabela 2'!O43 -> - | AH42: ='[3]Tabela 2'!B6 -> 47.00908
A43: =EDATE(A42,1) -> 37653 | B43: ='[1]Tabela 1'!B43 -> 43.32425 | C43: ='[2]Tabela 1'!B44 -> 81.84821 | D43: ='[2]Tabela 1'!C44 -> 48.93756 | E43: ='[2]Tabela 1'!D44 -> 48.03983 | F43: ='[2]Tabela 1'!E44 -> 68.43286 | G43: ='[2]Tabela 1'!F44 -> 28.55847 | H43: ='[2]Tabela 1'!G44 -> - | I43: ='[2]Tabela 1'!H44 -> - | J43: ='[2]Tabela 1'!I44 -> 23.3968 | ... P43: ='[2]Tabela 1'!O44 -> - | Q43: ='[3]Tabela 1'!B7 -> 44.07447 | R43: =B43-S43 -> -5.11744 | S43: ='[1]Tabela 2'!B43 -> 48.44169 | T43: ='[2]Tabela 2'!B44 -> 89.67826 | U43: ='[2]Tabela 2'!C44 -> 53.48672 | V43: ='[2]Tabela 2'!D44 -> 52.5767 | W43: ='[2]Tabela 2'!E44 -> 87.79634 | X43: ='[2]Tabela 2'!F44 -> 32.84447 | Y43: ='[2]Tabela 2'!G44 -> - | Z43: ='[2]Tabela 2'!H44 -> - | AA43: ='[2]Tabela 2'!I44 -> 25.39792 | ... AG43: ='[2]Tabela 2'!O44 -> - | AH43: ='[3]Tabela 2'!B7 -> 48.64951
A44: =EDATE(A43,1) -> 37681 | B44: ='[1]Tabela 1'!B44 -> 44.72463 | C44: ='[2]Tabela 1'!B45 -> 88.23938 | D44: ='[2]Tabela 1'!C45 -> 52.0502 | E44: ='[2]Tabela 1'!D45 -> 51.15274 | F44: ='[2]Tabela 1'!E45 -> 69.42464 | G44: ='[2]Tabela 1'!F45 -> 28.14003 | H44: ='[2]Tabela 1'!G45 -> - | I44: ='[2]Tabela 1'!H45 -> - | J44: ='[2]Tabela 1'!I45 -> 23.49896 | ... P44: ='[2]Tabela 1'!O45 -> - | Q44: ='[3]Tabela 1'!B8 -> 44.16825 | R44: =B44-S44 -> -2.39808 | S44: ='[1]Tabela 2'!B44 -> 47.12271 | T44: ='[2]Tabela 2'!B45 -> 90.19082 | U44: ='[2]Tabela 2'!C45 -> 52.3491 | V44: ='[2]Tabela 2'!D45 -> 51.36214 | W44: ='[2]Tabela 2'!E45 -> 88.19057 | X44: ='[2]Tabela 2'!F45 -> 31.36356 | Y44: ='[2]Tabela 2'!G45 -> - | Z44: ='[2]Tabela 2'!H45 -> - | AA44: ='[2]Tabela 2'!I45 -> 23.87234 | ... AG44: ='[2]Tabela 2'!O45 -> - | AH44: ='[3]Tabela 2'!B8 -> 47.27279
A45: =EDATE(A44,1) -> 37712 | B45: ='[1]Tabela 1'!B45 -> 45.42482 | C45: ='[2]Tabela 1'!B46 -> 88.03321 | D45: ='[2]Tabela 1'!C46 -> 52.7419 | E45: ='[2]Tabela 1'!D46 -> 51.65754 | F45: ='[2]Tabela 1'!E46 -> 74.50752 | G45: ='[2]Tabela 1'!F46 -> 28.24464 | H45: ='[2]Tabela 1'!G46 -> - | I45: ='[2]Tabela 1'!H46 -> - | J45: ='[2]Tabela 1'!I46 -> 24.21415 | ... P45: ='[2]Tabela 1'!O46 -> - | Q45: ='[3]Tabela 1'!B9 -> 45.106 | R45: =B45-S45 -> -1.74868 | S45: ='[1]Tabela 2'!B45 -> 47.1735 | T45: ='[2]Tabela 2'!B46 -> 90.50122 | U45: ='[2]Tabela 2'!C46 -> 52.45492 | V45: ='[2]Tabela 2'!D46 -> 51.49912 | W45: ='[2]Tabela 2'!E46 -> 87.71188 | X45: ='[2]Tabela 2'!F46 -> 31.74497 | Y45: ='[2]Tabela 2'!G46 -> - | Z45: ='[2]Tabela 2'!H46 -> - | AA45: ='[2]Tabela 2'!I46 -> 24.93551 | ... AG45: ='[2]Tabela 2'!O46 -> - | AH45: ='[3]Tabela 2'!B9 -> 47.17937
A46: =EDATE(A45,1) -> 37742 | B46: ='[1]Tabela 1'!B46 -> 47.43786 | C46: ='[2]Tabela 1'!B47 -> 92.98121 | D46: ='[2]Tabela 1'!C47 -> 52.30959 | E46: ='[2]Tabela 1'!D47 -> 51.40514 | F46: ='[2]Tabela 1'!E47 -> 82.68971 | G46: ='[2]Tabela 1'!F47 -> 33.1613 | H46: ='[2]Tabela 1'!G47 -> - | I46: ='[2]Tabela 1'!H47 -> - | J46: ='[2]Tabela 1'!I47 -> 25.79778 | ... P46: ='[2]Tabela 1'!O47 -> - | Q46: ='[3]Tabela 1'!B10 -> 47.07529 | R46: =B46-S46 -> 0.59272 | S46: ='[1]Tabela 2'!B46 -> 46.84514 | T46: ='[2]Tabela 2'!B47 -> 92.10275 | U46: ='[2]Tabela 2'!C47 -> 52.41504 | V46: ='[2]Tabela 2'!D47 -> 51.56535 | W46: ='[2]Tabela 2'!E47 -> 73.51995 | X46: ='[2]Tabela 2'!F47 -> 31.80281 | Y46: ='[2]Tabela 2'!G47 -> - | Z46: ='[2]Tabela 2'!H47 -> - | AA46: ='[2]Tabela 2'!I47 -> 24.8625 | ... AG46: ='[2]Tabela 2'!O47 -> - | AH46: ='[3]Tabela 2'!B10 -> 46.62564
A47: =EDATE(A46,1) -> 37773 | B47: ='[1]Tabela 1'!B47 -> 44.46205 | C47: ='[2]Tabela 1'!B48 -> 89.3733 | D47: ='[2]Tabela 1'!C48 -> 48.67818 | E47: ='[2]Tabela 1'!D48 -> 47.7033 | F47: ='[2]Tabela 1'!E48 -> 80.70615 | G47: ='[2]Tabela 1'!F48 -> 30.12761 | H47: ='[2]Tabela 1'!G48 -> - | I47: ='[2]Tabela 1'!H48 -> - | J47: ='[2]Tabela 1'!I48 -> 24.62283 | ... P47: ='[2]Tabela 1'!O48 -> - | Q47: ='[3]Tabela 1'!B11 -> 44.3558 | R47: =B47-S47 -> -2.66605 | S47: ='[1]Tabela 2'!B47 -> 47.1281 | T47: ='[2]Tabela 2'!B48 -> 90.84159 | U47: ='[2]Tabela 2'!C48 -> 52.08247 | V47: ='[2]Tabela 2'!D48 -> 51.10583 | W47: ='[2]Tabela 2'!E48 -> 79.63442 | X47: ='[2]Tabela 2'!F48 -> 32.78163 | Y47: ='[2]Tabela 2'!G48 -> - | Z47: ='[2]Tabela 2'!H48 -> - | AA47: ='[2]Tabela 2'!I48 -> 24.98221 | ... AG47: ='[2]Tabela 2'!O48 -> - | AH47: ='[3]Tabela 2'!B11 -> 47.09295
A48: =EDATE(A47,1) -> 37803 | B48: ='[1]Tabela 1'!B48 -> 47.00024 | C48: ='[2]Tabela 1'!B49 -> 98.75388 | D48: ='[2]Tabela 1'!C49 -> 51.3585 | E48: ='[2]Tabela 1'!D49 -> 50.31141 | F48: ='[2]Tabela 1'!E49 -> 82.06985 | G48: ='[2]Tabela 1'!F49 -> 32.84747 | H48: ='[2]Tabela 1'!G49 -> - | I48: ='[2]Tabela 1'!H49 -> - | J48: ='[2]Tabela 1'!I49 -> 26.10428 | ... P48: ='[2]Tabela 1'!O49 -> - | Q48: ='[3]Tabela 1'!B12 -> 47.73171 | R48: =B48-S48 -> -0.66967 | S48: ='[1]Tabela 2'!B48 -> 47.66991 | T48: ='[2]Tabela 2'!B49 -> 94.77138 | U48: ='[2]Tabela 2'!C49 -> 52.41441 | V48: ='[2]Tabela 2'!D49 -> 51.32895 | W48: ='[2]Tabela 2'!E49 -> 82.63087 | X48: ='[2]Tabela 2'!F49 -> 33.69662 | Y48: ='[2]Tabela 2'!G49 -> - | Z48: ='[2]Tabela 2'!H49 -> - | AA48: ='[2]Tabela 2'!I49 -> 25.54253 | ... AG48: ='[2]Tabela 2'!O49 -> - | AH48: ='[3]Tabela 2'!B12 -> 47.72093
... A302: =EDATE(A301,1) -> 45536 | B302: ='[1]Tabela 1'!B302 -> 102.30601 | C302: ='[2]Tabela 1'!B303 -> 103.15082 | D302: ='[2]Tabela 1'!C303 -> 105.42222 | E302: ='[2]Tabela 1'!D303 -> 106.68136 | F302: ='[2]Tabela 1'!E303 -> 82.97417 | G302: ='[2]Tabela 1'!F303 -> 96.15164 | H302: ='[2]Tabela 1'!G303 -> 91.9815 | I302: ='[2]Tabela 1'!H303 -> 99.38675 | J302: ='[2]Tabela 1'!I303 -> 120.26618 | ... P302: ='[2]Tabela 1'!O303 -> 88.08751 | Q302: ='[3]Tabela 1'!B266 -> 105.33063 | R302: =B302-S302 -> -4.99064 | S302: ='[1]Tabela 2'!B302 -> 107.29665 | T302: ='[2]Tabela 2'!B303 -> 101.88725 | U302: ='[2]Tabela 2'!C303 -> 109.33722 | V302: ='[2]Tabela 2'!D303 -> 110.89052 | W302: ='[2]Tabela 2'!E303 -> 96.35503 | X302: ='[2]Tabela 2'!F303 -> 102.8107 | Y302: ='[2]Tabela 2'!G303 -> - | Z302: ='[2]Tabela 2'!H303 -> - | AA302: ='[2]Tabela 2'!I303 -> 124.32019 | ... AG302: ='[2]Tabela 2'!O303 -> - | AH302: ='[3]Tabela 2'!B266 -> 108.43218

Sheet MoM
A1: ÍNDICE DE PESOS | B1: VOLUME DE VENDAS NO VAREJO - BRASIL (Base: MÉDIA 2011=100)
C2: 0.121 | D2: 0.54 | F2: 0.063 | G2: 0.069 | J2: 0.093 | K2: 0.003 | L2: 0.014 | M2: 0.097 | O2: 0.077 | Q2: 0.841
B3: DADOS ORIGINAIS
A4: Período | B4: Comércio Varejista | C4: 1. Combustiveis e Lubrificantes | D4: 2. Hipermercados, supermercados, prod. alimenticios, bebidas e fumo | F4: 3. Tecidos, vestuario e calçados | G4: 4. Móveis e Eletrodomésticos | H4: Móveis | I4: Eletrodomésticos | J4: 5. Demais artigos de uso pessoal e doméstico | N4: 6. Veículos, motos, partes e peças | O4: 7. Material de Construção | P4: 8. Atacado especializado em produtos alimenticios, bebidas e fumo | Q4: Comércio Varejista Ampliado
D5: Total | E5: 2.1 Supermercados e Hipermercados | J5: Artigos farmaceuticos, médicos, ortopédicos, de perfumaria e cosméticos | K5: Livros Jornais, revistas e papelaria | L5: Equipamentos e materiais para escritório, informática e comunicação | M5: Outros artigos de uso pessoal e domésticos
A6: 36526 | B6: =ENTRADA!S6/ENTRADA!S5-1 -> #DIV/0! | C6: =ENTRADA!T6/ENTRADA!T5-1 -> #DIV/0! | D6: =ENTRADA!U6/ENTRADA!U5-1 -> #VALUE! | E6: =ENTRADA!V6/ENTRADA!V5-1 -> #VALUE! | F6: =ENTRADA!W6/ENTRADA!W5-1 -> #DIV/0! | G6: =ENTRADA!X6/ENTRADA!X5-1 -> #DIV/0! | J6: =ENTRADA!AA6/ENTRADA!AA5-1 -> #VALUE! | K6: =ENTRADA!AB6/ENTRADA!AB5-1 -> #VALUE! | L6: =ENTRADA!AC6/ENTRADA!AC5-1 -> #VALUE! | M6: =ENTRADA!AD6/ENTRADA!AD5-1 -> #VALUE! | N6: =ENTRADA!AE6/ENTRADA!AE5-1 -> #DIV/0! | O6: =ENTRADA!AF6/ENTRADA!AF5-1 -> #VALUE! | Q6: =ENTRADA!AH6/ENTRADA!AH5-1 -> #REF!
A7: =EDATE(A6,1) -> 36557 | B7: =ENTRADA!S7/ENTRADA!S6-1 -> 0.0089319129 | C7: =ENTRADA!T7/ENTRADA!T6-1 -> -0.0065707208 | D7: =ENTRADA!U7/ENTRADA!U6-1 -> 0.010350366 | E7: =ENTRADA!V7/ENTRADA!V6-1 -> 0.0064800503 | F7: =ENTRADA!W7/ENTRADA!W6-1 -> 0.01608576 | G7: =ENTRADA!X7/ENTRADA!X6-1 -> 0.03240177 | J7: =ENTRADA!AA7/ENTRADA!AA6-1 -> #VALUE! | K7: =ENTRADA!AB7/ENTRADA!AB6-1 -> #VALUE! | L7: =ENTRADA!AC7/ENTRADA!AC6-1 -> #VALUE! | M7: =ENTRADA!AD7/ENTRADA!AD6-1 -> #VALUE! | N7: =ENTRADA!AE7/ENTRADA!AE6-1 -> 0.16428357 | O7: =ENTRADA!AF7/ENTRADA!AF6-1 -> #VALUE! | Q7: =ENTRADA!AH7/ENTRADA!AH6-1 -> #REF!
A8: =EDATE(A7,1) -> 36586 | B8: =ENTRADA!S8/ENTRADA!S7-1 -> 0.0061758624 | C8: =ENTRADA!T8/ENTRADA!T7-1 -> -0.0050478038 | D8: =ENTRADA!U8/ENTRADA!U7-1 -> 0.0011959379 | E8: =ENTRADA!V8/ENTRADA!V7-1 -> 0.005007715 | F8: =ENTRADA!W8/ENTRADA!W7-1 -> 0.020434255 | G8: =ENTRADA!X8/ENTRADA!X7-1 -> 0.010534022 | J8: =ENTRADA!AA8/ENTRADA!AA7-1 -> #VALUE! | K8: =ENTRADA!AB8/ENTRADA!AB7-1 -> #VALUE! | L8: =ENTRADA!AC8/ENTRADA!AC7-1 -> #VALUE! | M8: =ENTRADA!AD8/ENTRADA!AD7-1 -> #VALUE! | N8: =ENTRADA!AE8/ENTRADA!AE7-1 -> -0.029021121 | O8: =ENTRADA!AF8/ENTRADA!AF7-1 -> #VALUE! | Q8: =ENTRADA!AH8/ENTRADA!AH7-1 -> #REF!
A9: =EDATE(A8,1) -> 36617 | B9: =ENTRADA!S9/ENTRADA!S8-1 -> 0.00097634557 | C9: =ENTRADA!T9/ENTRADA!T8-1 -> 0.0034921177 | D9: =ENTRADA!U9/ENTRADA!U8-1 -> 0.00064783887 | E9: =ENTRADA!V9/ENTRADA!V8-1 -> 0.0043594733 | F9: =ENTRADA!W9/ENTRADA!W8-1 -> 0.016815247 | G9: =ENTRADA!X9/ENTRADA!X8-1 -> -0.0054015004 | J9: =ENTRADA!AA9/ENTRADA!AA8-1 -> #VALUE! | K9: =ENTRADA!AB9/ENTRADA!AB8-1 -> #VALUE! | L9: =ENTRADA!AC9/ENTRADA!AC8-1 -> #VALUE! | M9: =ENTRADA!AD9/ENTRADA!AD8-1 -> #VALUE! | N9: =ENTRADA!AE9/ENTRADA!AE8-1 -> -0.023870508 | O9: =ENTRADA!AF9/ENTRADA!AF8-1 -> #VALUE! | Q9: =ENTRADA!AH9/ENTRADA!AH8-1 -> #REF!
A10: =EDATE(A9,1) -> 36647 | B10: =ENTRADA!S10/ENTRADA!S9-1 -> 0.0060552476 | C10: =ENTRADA!T10/ENTRADA!T9-1 -> -0.02681678 | D10: =ENTRADA!U10/ENTRADA!U9-1 -> 0.0080918404 | E10: =ENTRADA!V10/ENTRADA!V9-1 -> 0.0064169845 | F10: =ENTRADA!W10/ENTRADA!W9-1 -> -0.017016267 | G10: =ENTRADA!X10/ENTRADA!X9-1 -> 0.024104204 | J10: =ENTRADA!AA10/ENTRADA!AA9-1 -> #VALUE! | K10: =ENTRADA!AB10/ENTRADA!AB9-1 -> #VALUE! | L10: =ENTRADA!AC10/ENTRADA!AC9-1 -> #VALUE! | M10: =ENTRADA!AD10/ENTRADA!AD9-1 -> #VALUE! | N10: =ENTRADA!AE10/ENTRADA!AE9-1 -> 0.058733194 | O10: =ENTRADA!AF10/ENTRADA!AF9-1 -> #VALUE! | Q10: =ENTRADA!AH10/ENTRADA!AH9-1 -> #REF!
A11: =EDATE(A10,1) -> 36678 | B11: =ENTRADA!S11/ENTRADA!S10-1 -> -0.0024022549 | C11: =ENTRADA!T11/ENTRADA!T10-1 -> -0.0019848848 | D11: =ENTRADA!U11/ENTRADA!U10-1 -> 0.0169324 | E11: =ENTRADA!V11/ENTRADA!V10-1 -> 0.015011995 | F11: =ENTRADA!W11/ENTRADA!W10-1 -> 0.0080587365 | G11: =ENTRADA!X11/ENTRADA!X10-1 -> 0.017115932 | J11: =ENTRADA!AA11/ENTRADA!AA10-1 -> #VALUE! | K11: =ENTRADA!AB11/ENTRADA!AB10-1 -> #VALUE! | L11: =ENTRADA!AC11/ENTRADA!AC10-1 -> #VALUE! | M11: =ENTRADA!AD11/ENTRADA!AD10-1 -> #VALUE! | N11: =ENTRADA!AE11/ENTRADA!AE10-1 -> -0.023977808 | O11: =ENTRADA!AF11/ENTRADA!AF10-1 -> #VALUE! | Q11: =ENTRADA!AH11/ENTRADA!AH10-1 -> #REF!
A12: =EDATE(A11,1) -> 36708 | B12: =ENTRADA!S12/ENTRADA!S11-1 -> 0.0031005197 | C12: =ENTRADA!T12/ENTRADA!T11-1 -> -0.020840452 | D12: =ENTRADA!U12/ENTRADA!U11-1 -> -0.0017780035 | E12: =ENTRADA!V12/ENTRADA!V11-1 -> 0.00038951187 | F12: =ENTRADA!W12/ENTRADA!W11-1 -> 0.00014869776 | G12: =ENTRADA!X12/ENTRADA!X11-1 -> 0.019399044 | J12: =ENTRADA!AA12/ENTRADA!AA11-1 -> #VALUE! | K12: =ENTRADA!AB12/ENTRADA!AB11-1 -> #VALUE! | L12: =ENTRADA!AC12/ENTRADA!AC11-1 -> #VALUE! | M12: =ENTRADA!AD12/ENTRADA!AD11-1 -> #VALUE! | N12: =ENTRADA!AE12/ENTRADA!AE11-1 -> 0.023961808 | O12: =ENTRADA!AF12/ENTRADA!AF11-1 -> #VALUE! | Q12: =ENTRADA!AH12/ENTRADA!AH11-1 -> #REF!
A13: =EDATE(A12,1) -> 36739 | B13: =ENTRADA!S13/ENTRADA!S12-1 -> -0.0081829217 | C13: =ENTRADA!T13/ENTRADA!T12-1 -> -0.050919701 | D13: =ENTRADA!U13/ENTRADA!U12-1 -> -0.0047838964 | E13: =ENTRADA!V13/ENTRADA!V12-1 -> -0.0056798854 | F13: =ENTRADA!W13/ENTRADA!W12-1 -> -0.013321158 | G13: =ENTRADA!X13/ENTRADA!X12-1 -> 0.01351403 | J13: =ENTRADA!AA13/ENTRADA!AA12-1 -> #VALUE! | K13: =ENTRADA!AB13/ENTRADA!AB12-1 -> #VALUE! | L13: =ENTRADA!AC13/ENTRADA!AC12-1 -> #VALUE! | M13: =ENTRADA!AD13/ENTRADA!AD12-1 -> #VALUE! | N13: =ENTRADA!AE13/ENTRADA!AE12-1 -> 0.04593755 | O13: =ENTRADA!AF13/ENTRADA!AF12-1 -> #VALUE! | Q13: =ENTRADA!AH13/ENTRADA!AH12-1 -> #REF!
A14: =EDATE(A13,1) -> 36770 | B14: =ENTRADA!S14/ENTRADA!S13-1 -> 0.0015826842 | C14: =ENTRADA!T14/ENTRADA!T13-1 -> 0.021109892 | D14: =ENTRADA!U14/ENTRADA!U13-1 -> 0.006959499 | E14: =ENTRADA!V14/ENTRADA!V13-1 -> 0.0083132426 | F14: =ENTRADA!W14/ENTRADA!W13-1 -> 0.0091955513 | G14: =ENTRADA!X14/ENTRADA!X13-1 -> -0.0050444579 | J14: =ENTRADA!AA14/ENTRADA!AA13-1 -> #VALUE! | K14: =ENTRADA!AB14/ENTRADA!AB13-1 -> #VALUE! | L14: =ENTRADA!AC14/ENTRADA!AC13-1 -> #VALUE! | M14: =ENTRADA!AD14/ENTRADA!AD13-1 -> #VALUE! | N14: =ENTRADA!AE14/ENTRADA!AE13-1 -> -0.071132092 | O14: =ENTRADA!AF14/ENTRADA!AF13-1 -> #VALUE! | Q14: =ENTRADA!AH14/ENTRADA!AH13-1 -> #REF!
A15: =EDATE(A14,1) -> 36800 | B15: =ENTRADA!S15/ENTRADA!S14-1 -> -0.014298756 | C15: =ENTRADA!T15/ENTRADA!T14-1 -> 0.0025682626 | D15: =ENTRADA!U15/ENTRADA!U14-1 -> -0.019664364 | E15: =ENTRADA!V15/ENTRADA!V14-1 -> -0.01627351 | F15: =ENTRADA!W15/ENTRADA!W14-1 -> -0.035616092 | G15: =ENTRADA!X15/ENTRADA!X14-1 -> -0.037979155 | J15: =ENTRADA!AA15/ENTRADA!AA14-1 -> #VALUE! | K15: =ENTRADA!AB15/ENTRADA!AB14-1 -> #VALUE! | L15: =ENTRADA!AC15/ENTRADA!AC14-1 -> #VALUE! | M15: =ENTRADA!AD15/ENTRADA!AD14-1 -> #VALUE! | N15: =ENTRADA!AE15/ENTRADA!AE14-1 -> 0.031387539 | O15: =ENTRADA!AF15/ENTRADA!AF14-1 -> #VALUE! | Q15: =ENTRADA!AH15/ENTRADA!AH14-1 -> #REF!
A16: =EDATE(A15,1) -> 36831 | B16: =ENTRADA!S16/ENTRADA!S15-1 -> 0.016984083 | C16: =ENTRADA!T16/ENTRADA!T15-1 -> -0.0063438903 | D16: =ENTRADA!U16/ENTRADA!U15-1 -> 0.01355918 | E16: =ENTRADA!V16/ENTRADA!V15-1 -> 0.0087706999 | F16: =ENTRADA!W16/ENTRADA!W15-1 -> 0.028291646 | G16: =ENTRADA!X16/ENTRADA!X15-1 -> 0.048094319 | J16: =ENTRADA!AA16/ENTRADA!AA15-1 -> #VALUE! | K16: =ENTRADA!AB16/ENTRADA!AB15-1 -> #VALUE! | L16: =ENTRADA!AC16/ENTRADA!AC15-1 -> #VALUE! | M16: =ENTRADA!AD16/ENTRADA!AD15-1 -> #VALUE! | N16: =ENTRADA!AE16/ENTRADA!AE15-1 -> 0.029029927 | O16: =ENTRADA!AF16/ENTRADA!AF15-1 -> #VALUE! | Q16: =ENTRADA!AH16/ENTRADA!AH15-1 -> #REF!
A17: =EDATE(A16,1) -> 36861 | B17: =ENTRADA!S17/ENTRADA!S16-1 -> 0.0024946539 | C17: =ENTRADA!T17/ENTRADA!T16-1 -> 0.0040483893 | D17: =ENTRADA!U17/ENTRADA!U16-1 -> 0.014334179 | E17: =ENTRADA!V17/ENTRADA!V16-1 -> 0.014879645 | F17: =ENTRADA!W17/ENTRADA!W16-1 -> -0.0069602879 | G17: =ENTRADA!X17/ENTRADA!X16-1 -> -0.0016060548 | J17: =ENTRADA!AA17/ENTRADA!AA16-1 -> #VALUE! | K17: =ENTRADA!AB17/ENTRADA!AB16-1 -> #VALUE! | L17: =ENTRADA!AC17/ENTRADA!AC16-1 -> #VALUE! | M17: =ENTRADA!AD17/ENTRADA!AD16-1 -> #VALUE! | N17: =ENTRADA!AE17/ENTRADA!AE16-1 -> -0.013158987 | O17: =ENTRADA!AF17/ENTRADA!AF16-1 -> #VALUE! | Q17: =ENTRADA!AH17/ENTRADA!AH16-1 -> #REF!
A18: =EDATE(A17,1) -> 36892 | B18: =ENTRADA!S18/ENTRADA!S17-1 -> -0.0021532302 | C18: =ENTRADA!T18/ENTRADA!T17-1 -> 0.0075009947 | D18: =ENTRADA!U18/ENTRADA!U17-1 -> 0.0035711566 | E18: =ENTRADA!V18/ENTRADA!V17-1 -> 0.00094408634 | F18: =ENTRADA!W18/ENTRADA!W17-1 -> 0.02520598 | G18: =ENTRADA!X18/ENTRADA!X17-1 -> -0.0066060657 | J18: =ENTRADA!AA18/ENTRADA!AA17-1 -> #VALUE! | K18: =ENTRADA!AB18/ENTRADA!AB17-1 -> #VALUE! | L18: =ENTRADA!AC18/ENTRADA!AC17-1 -> #VALUE! | M18: =ENTRADA!AD18/ENTRADA!AD17-1 -> #VALUE! | N18: =ENTRADA!AE18/ENTRADA!AE17-1 -> 0.026500026 | O18: =ENTRADA!AF18/ENTRADA!AF17-1 -> #VALUE! | Q18: =ENTRADA!AH18/ENTRADA!AH17-1 -> #REF!
... A302: =EDATE(A301,1) -> 45536 | B302: =ENTRADA!S302/ENTRADA!S301-1 -> 0.0075027022 | C302: =ENTRADA!T302/ENTRADA!T301-1 -> 0.02645575 | D302: =ENTRADA!U302/ENTRADA!U301-1 -> 0.0073010454 | E302: =ENTRADA!V302/ENTRADA!V301-1 -> 0.010324872 | F302: =ENTRADA!W302/ENTRADA!W301-1 -> -0.020691749 | G302: =ENTRADA!X302/ENTRADA!X301-1 -> -0.037702505 | J302: =ENTRADA!AA302/ENTRADA!AA301-1 -> 0.018507779 | K302: =ENTRADA!AB302/ENTRADA!AB301-1 -> -0.019267848 | L302: =ENTRADA!AC302/ENTRADA!AC301-1 -> -0.02095917 | M302: =ENTRADA!AD302/ENTRADA!AD301-1 -> 0.031297381 | N302: =ENTRADA!AE302/ENTRADA!AE301-1 -> 0.06375443 | O302: =ENTRADA!AF302/ENTRADA!AF301-1 -> 0.016470124 | Q302: =ENTRADA!AH302/ENTRADA!AH301-1 -> 0.02496408

Sheet QoQ
B1: VOLUME DE VENDAS NO VAREJO - BRASIL (Base: MÉDIA 2011=100)
B3: DADOS DESSAZONALIZADOS
A4: Período | B4: Comércio Varejista | C4: 1. Combustiveis e Lubrificantes | D4: 2. Hipermercados, supermercados, prod. alimenticios, bebidas e fumo | F4: 3. Tecidos, vestuario e calçados | G4: 4. Móveis e Eletrodomésticos | H4: Móveis | I4: Eletrodomésticos | J4: 5. Demais artigos de uso pessoal e doméstico | N4: 6. Veículos, motos, partes e peças | O4: 7. Material de Construção | P4: Comércio Varejista Ampliado
D5: Total | E5: 2.1 Supermercados e Hipermercados | J5: Artigos farmaceuticos, médicos, ortopédicos, de perfumaria e cosméticos | K5: Livros Jornais, revistas e papelaria | L5: Equipamentos e materiais para escritório, informática e comunicação | M5: Outros artigos de uso pessoal e domésticos
A6: =ENTRADA!A6 -> 36526 | B6: =SUM(ENTRADA!S4:S6)/SUM(ENTRADA!S1:S3)-1 -> #DIV/0! | C6: =SUM(ENTRADA!T4:T6)/SUM(ENTRADA!T1:T3)-1 -> #DIV/0! | D6: =SUM(ENTRADA!U4:U6)/SUM(ENTRADA!U1:U3)-1 -> #DIV/0! | E6: =SUM(ENTRADA!V4:V6)/SUM(ENTRADA!V1:V3)-1 -> #DIV/0! | F6: =SUM(ENTRADA!W4:W6)/SUM(ENTRADA!W1:W3)-1 -> #DIV/0! | G6: =SUM(ENTRADA!X4:X6)/SUM(ENTRADA!X1:X3)-1 -> #DIV/0! | J6: =SUM(ENTRADA!AA4:AA6)/SUM(ENTRADA!AA1:AA3)-1 -> #DIV/0! | K6: =SUM(ENTRADA!AB4:AB6)/SUM(ENTRADA!AB1:AB3)-1 -> #DIV/0! | L6: =SUM(ENTRADA!AC4:AC6)/SUM(ENTRADA!AC1:AC3)-1 -> #DIV/0! | M6: =SUM(ENTRADA!AD4:AD6)/SUM(ENTRADA!AD1:AD3)-1 -> #DIV/0! | N6: =SUM(ENTRADA!AE4:AE6)/SUM(ENTRADA!AE1:AE3)-1 -> #DIV/0! | O6: =SUM(ENTRADA!AF4:AF6)/SUM(ENTRADA!AF1:AF3)-1 -> #DIV/0! | P6: =SUM(ENTRADA!AH4:AH6)/SUM(ENTRADA!AH1:AH3)-1 -> #REF!
A7: =ENTRADA!A7 -> 36557 | B7: =SUM(ENTRADA!S5:S7)/SUM(ENTRADA!S2:S4)-1 -> #DIV/0! | C7: =SUM(ENTRADA!T5:T7)/SUM(ENTRADA!T2:T4)-1 -> #DIV/0! | D7: =SUM(ENTRADA!U5:U7)/SUM(ENTRADA!U2:U4)-1 -> #DIV/0! | E7: =SUM(ENTRADA!V5:V7)/SUM(ENTRADA!V2:V4)-1 -> #DIV/0! | F7: =SUM(ENTRADA!W5:W7)/SUM(ENTRADA!W2:W4)-1 -> #DIV/0! | G7: =SUM(ENTRADA!X5:X7)/SUM(ENTRADA!X2:X4)-1 -> #DIV/0! | J7: =SUM(ENTRADA!AA5:AA7)/SUM(ENTRADA!AA2:AA4)-1 -> #DIV/0! | K7: =SUM(ENTRADA!AB5:AB7)/SUM(ENTRADA!AB2:AB4)-1 -> #DIV/0! | L7: =SUM(ENTRADA!AC5:AC7)/SUM(ENTRADA!AC2:AC4)-1 -> #DIV/0! | M7: =SUM(ENTRADA!AD5:AD7)/SUM(ENTRADA!AD2:AD4)-1 -> #DIV/0! | N7: =SUM(ENTRADA!AE5:AE7)/SUM(ENTRADA!AE2:AE4)-1 -> #DIV/0! | O7: =SUM(ENTRADA!AF5:AF7)/SUM(ENTRADA!AF2:AF4)-1 -> #DIV/0! | P7: =SUM(ENTRADA!AH5:AH7)/SUM(ENTRADA!AH2:AH4)-1 -> #REF!
A8: =ENTRADA!A8 -> 36586 | B8: =SUM(ENTRADA!S6:S8)/SUM(ENTRADA!S3:S5)-1 -> #DIV/0! | C8: =SUM(ENTRADA!T6:T8)/SUM(ENTRADA!T3:T5)-1 -> #DIV/0! | D8: =SUM(ENTRADA!U6:U8)/SUM(ENTRADA!U3:U5)-1 -> #DIV/0! | E8: =SUM(ENTRADA!V6:V8)/SUM(ENTRADA!V3:V5)-1 -> #DIV/0! | F8: =SUM(ENTRADA!W6:W8)/SUM(ENTRADA!W3:W5)-1 -> #DIV/0! | G8: =SUM(ENTRADA!X6:X8)/SUM(ENTRADA!X3:X5)-1 -> #DIV/0! | J8: =SUM(ENTRADA!AA6:AA8)/SUM(ENTRADA!AA3:AA5)-1 -> #DIV/0! | K8: =SUM(ENTRADA!AB6:AB8)/SUM(ENTRADA!AB3:AB5)-1 -> #DIV/0! | L8: =SUM(ENTRADA!AC6:AC8)/SUM(ENTRADA!AC3:AC5)-1 -> #DIV/0! | M8: =SUM(ENTRADA!AD6:AD8)/SUM(ENTRADA!AD3:AD5)-1 -> #DIV/0! | N8: =SUM(ENTRADA!AE6:AE8)/SUM(ENTRADA!AE3:AE5)-1 -> #DIV/0! | O8: =SUM(ENTRADA!AF6:AF8)/SUM(ENTRADA!AF3:AF5)-1 -> #DIV/0! | P8: =SUM(ENTRADA!AH6:AH8)/SUM(ENTRADA!AH3:AH5)-1 -> #REF!
A9: =ENTRADA!A9 -> 36617 | B9: =SUM(ENTRADA!S7:S9)/SUM(ENTRADA!S4:S6)-1 -> 2.0402489 | C9: =SUM(ENTRADA!T7:T9)/SUM(ENTRADA!T4:T6)-1 -> 1.9737102 | D9: =SUM(ENTRADA!U7:U9)/SUM(ENTRADA!U4:U6)-1 -> 2.0341231 | E9: =SUM(ENTRADA!V7:V9)/SUM(ENTRADA!V4:V6)-1 -> 2.0339302 | F9: =SUM(ENTRADA!W7:W9)/SUM(ENTRADA!W4:W6)-1 -> 2.1072181 | G9: =SUM(ENTRADA!X7:X9)/SUM(ENTRADA!X4:X6)-1 -> 2.1133207 | J9: =SUM(ENTRADA!AA7:AA9)/SUM(ENTRADA!AA4:AA6)-1 -> #DIV/0! | K9: =SUM(ENTRADA!AB7:AB9)/SUM(ENTRADA!AB4:AB6)-1 -> #DIV/0! | L9: =SUM(ENTRADA!AC7:AC9)/SUM(ENTRADA!AC4:AC6)-1 -> #DIV/0! | M9: =SUM(ENTRADA!AD7:AD9)/SUM(ENTRADA!AD4:AD6)-1 -> #DIV/0! | N9: =SUM(ENTRADA!AE7:AE9)/SUM(ENTRADA!AE4:AE6)-1 -> 2.3982876 | O9: =SUM(ENTRADA!AF7:AF9)/SUM(ENTRADA!AF4:AF6)-1 -> #DIV/0! | P9: =SUM(ENTRADA!AH7:AH9)/SUM(ENTRADA!AH4:AH6)-1 -> #REF!
A10: =ENTRADA!A10 -> 36647 | B10: =SUM(ENTRADA!S8:S10)/SUM(ENTRADA!S5:S7)-1 -> 0.52002373 | C10: =SUM(ENTRADA!T8:T10)/SUM(ENTRADA!T5:T7)-1 -> 0.47762884 | D10: =SUM(ENTRADA!U8:U10)/SUM(ENTRADA!U5:U7)-1 -> 0.51425216 | E10: =SUM(ENTRADA!V8:V10)/SUM(ENTRADA!V5:V7)-1 -> 0.5200247 | F10: =SUM(ENTRADA!W8:W10)/SUM(ENTRADA!W5:W7)-1 -> 0.55126135 | G10: =SUM(ENTRADA!X8:X10)/SUM(ENTRADA!X5:X7)-1 -> 0.54672781 | J10: =SUM(ENTRADA!AA8:AA10)/SUM(ENTRADA!AA5:AA7)-1 -> #DIV/0! | K10: =SUM(ENTRADA!AB8:AB10)/SUM(ENTRADA!AB5:AB7)-1 -> #DIV/0! | L10: =SUM(ENTRADA!AC8:AC10)/SUM(ENTRADA!AC5:AC7)-1 -> #DIV/0! | M10: =SUM(ENTRADA!AD8:AD10)/SUM(ENTRADA!AD5:AD7)-1 -> #DIV/0! | N10: =SUM(ENTRADA!AE8:AE10)/SUM(ENTRADA!AE5:AE7)-1 -> 0.57203334 | O10: =SUM(ENTRADA!AF8:AF10)/SUM(ENTRADA!AF5:AF7)-1 -> #DIV/0! | P10: =SUM(ENTRADA!AH8:AH10)/SUM(ENTRADA!AH5:AH7)-1 -> #REF!
A11: =ENTRADA!A11 -> 36678 | B11: =SUM(ENTRADA!S9:S11)/SUM(ENTRADA!S6:S8)-1 -> 0.011315022 | C11: =SUM(ENTRADA!T9:T11)/SUM(ENTRADA!T6:T8)-1 -> -0.020577294 | D11: =SUM(ENTRADA!U9:U11)/SUM(ENTRADA!U6:U8)-1 -> 0.016013794 | E11: =SUM(ENTRADA!V9:V11)/SUM(ENTRADA!V6:V8)-1 -> 0.019276632 | F11: =SUM(ENTRADA!W9:W11)/SUM(ENTRADA!W6:W8)-1 -> 0.026986479 | G11: =SUM(ENTRADA!X9:X11)/SUM(ENTRADA!X6:X8)-1 -> 0.034287727 | J11: =SUM(ENTRADA!AA9:AA11)/SUM(ENTRADA!AA6:AA8)-1 -> #DIV/0! | K11: =SUM(ENTRADA!AB9:AB11)/SUM(ENTRADA!AB6:AB8)-1 -> #DIV/0! | L11: =SUM(ENTRADA!AC9:AC11)/SUM(ENTRADA!AC6:AC8)-1 -> #DIV/0! | M11: =SUM(ENTRADA!AD9:AD11)/SUM(ENTRADA!AD6:AD8)-1 -> #DIV/0! | N11: =SUM(ENTRADA!AE9:AE11)/SUM(ENTRADA!AE6:AE8)-1 -> 0.035620284 | O11: =SUM(ENTRADA!AF9:AF11)/SUM(ENTRADA!AF6:AF8)-1 -> #DIV/0! | P11: =SUM(ENTRADA!AH9:AH11)/SUM(ENTRADA!AH6:AH8)-1 -> #REF!
A12: =ENTRADA!A12 -> 36708 | B12: =SUM(ENTRADA!S10:S12)/SUM(ENTRADA!S7:S9)-1 -> 0.0081976518 | C12: =SUM(ENTRADA!T10:T12)/SUM(ENTRADA!T7:T9)-1 -> -0.034238666 | D12: =SUM(ENTRADA!U10:U12)/SUM(ENTRADA!U7:U9)-1 -> 0.019709744 | E12: =SUM(ENTRADA!V10:V12)/SUM(ENTRADA!V7:V9)-1 -> 0.021265951 | F12: =SUM(ENTRADA!W10:W12)/SUM(ENTRADA!W7:W9)-1 -> 0.0060090284 | G12: =SUM(ENTRADA!X10:X12)/SUM(ENTRADA!X7:X9)-1 -> 0.042393099 | J12: =SUM(ENTRADA!AA10:AA12)/SUM(ENTRADA!AA7:AA9)-1 -> #DIV/0! | K12: =SUM(ENTRADA!AB10:AB12)/SUM(ENTRADA!AB7:AB9)-1 -> #DIV/0! | L12: =SUM(ENTRADA!AC10:AC12)/SUM(ENTRADA!AC7:AC9)-1 -> #DIV/0! | M12: =SUM(ENTRADA!AD10:AD12)/SUM(ENTRADA!AD7:AD9)-1 -> #DIV/0! | N12: =SUM(ENTRADA!AE10:AE12)/SUM(ENTRADA!AE7:AE9)-1 -> 0.022945185 | O12: =SUM(ENTRADA!AF10:AF12)/SUM(ENTRADA!AF7:AF9)-1 -> #DIV/0! | P12: =SUM(ENTRADA!AH10:AH12)/SUM(ENTRADA!AH7:AH9)-1 -> #REF!
A13: =ENTRADA!A13 -> 36739 | B13: =SUM(ENTRADA!S11:S13)/SUM(ENTRADA!S8:S10)-1 -> 0.0012714896 | C13: =SUM(ENTRADA!T11:T13)/SUM(ENTRADA!T8:T10)-1 -> -0.04877806 | D13: =SUM(ENTRADA!U11:U13)/SUM(ENTRADA!U8:U10)-1 -> 0.01978368 | E13: =SUM(ENTRADA!V11:V13)/SUM(ENTRADA!V8:V10)-1 -> 0.019150374 | F13: =SUM(ENTRADA!W11:W13)/SUM(ENTRADA!W8:W10)-1 -> -0.0022376337 | G13: =SUM(ENTRADA!X11:X13)/SUM(ENTRADA!X8:X10)-1 -> 0.04955419 | J13: =SUM(ENTRADA!AA11:AA13)/SUM(ENTRADA!AA8:AA10)-1 -> #DIV/0! | K13: =SUM(ENTRADA!AB11:AB13)/SUM(ENTRADA!AB8:AB10)-1 -> #DIV/0! | L13: =SUM(ENTRADA!AC11:AC13)/SUM(ENTRADA!AC8:AC10)-1 -> #DIV/0! | M13: =SUM(ENTRADA!AD11:AD13)/SUM(ENTRADA!AD8:AD10)-1 -> #DIV/0! | N13: =SUM(ENTRADA!AE11:AE13)/SUM(ENTRADA!AE8:AE10)-1 -> 0.037293372 | O13: =SUM(ENTRADA!AF11:AF13)/SUM(ENTRADA!AF8:AF10)-1 -> #DIV/0! | P13: =SUM(ENTRADA!AH11:AH13)/SUM(ENTRADA!AH8:AH10)-1 -> #REF!
A14: =ENTRADA!A14 -> 36770 | B14: =SUM(ENTRADA!S12:S14)/SUM(ENTRADA!S9:S11)-1 -> -0.001441655 | C14: =SUM(ENTRADA!T12:T14)/SUM(ENTRADA!T9:T11)-1 -> -0.057464644 | D14: =SUM(ENTRADA!U12:U14)/SUM(ENTRADA!U9:U11)-1 -> 0.011228608 | E14: =SUM(ENTRADA!V12:V14)/SUM(ENTRADA!V9:V11)-1 -> 0.011448618 | F14: =SUM(ENTRADA!W12:W14)/SUM(ENTRADA!W9:W11)-1 -> -0.0061007919 | G14: =SUM(ENTRADA!X12:X14)/SUM(ENTRADA!X9:X11)-1 -> 0.046661507 | J14: =SUM(ENTRADA!AA12:AA14)/SUM(ENTRADA!AA9:AA11)-1 -> #DIV/0! | K14: =SUM(ENTRADA!AB12:AB14)/SUM(ENTRADA!AB9:AB11)-1 -> #DIV/0! | L14: =SUM(ENTRADA!AC12:AC14)/SUM(ENTRADA!AC9:AC11)-1 -> #DIV/0! | M14: =SUM(ENTRADA!AD12:AD14)/SUM(ENTRADA!AD9:AD11)-1 -> #DIV/0! | N14: =SUM(ENTRADA!AE12:AE14)/SUM(ENTRADA!AE9:AE11)-1 -> 0.032578203 | O14: =SUM(ENTRADA!AF12:AF14)/SUM(ENTRADA!AF9:AF11)-1 -> #DIV/0! | P14: =SUM(ENTRADA!AH12:AH14)/SUM(ENTRADA!AH9:AH11)-1 -> #REF!
A15: =ENTRADA!A15 -> 36800 | B15: =SUM(ENTRADA!S13:S15)/SUM(ENTRADA!S10:S12)-1 -> -0.01062413 | C15: =SUM(ENTRADA!T13:T15)/SUM(ENTRADA!T10:T12)-1 -> -0.050843933 | D15: =SUM(ENTRADA!U13:U15)/SUM(ENTRADA!U10:U12)-1 -> -0.0023730382 | E15: =SUM(ENTRADA!V13:V15)/SUM(ENTRADA!V10:V12)-1 -> -0.00042228183 | F15: =SUM(ENTRADA!W13:W15)/SUM(ENTRADA!W10:W12)-1 -> -0.016375814 | G15: =SUM(ENTRADA!X13:X15)/SUM(ENTRADA!X10:X12)-1 -> 0.015816366 | J15: =SUM(ENTRADA!AA13:AA15)/SUM(ENTRADA!AA10:AA12)-1 -> #DIV/0! | K15: =SUM(ENTRADA!AB13:AB15)/SUM(ENTRADA!AB10:AB12)-1 -> #DIV/0! | L15: =SUM(ENTRADA!AC13:AC15)/SUM(ENTRADA!AC10:AC12)-1 -> #DIV/0! | M15: =SUM(ENTRADA!AD13:AD15)/SUM(ENTRADA!AD10:AD12)-1 -> #DIV/0! | N15: =SUM(ENTRADA!AE13:AE15)/SUM(ENTRADA!AE10:AE12)-1 -> 0.014213926 | O15: =SUM(ENTRADA!AF13:AF15)/SUM(ENTRADA!AF10:AF12)-1 -> #DIV/0! | P15: =SUM(ENTRADA!AH13:AH15)/SUM(ENTRADA!AH10:AH12)-1 -> #REF!
A16: =ENTRADA!A16 -> 36831 | B16: =SUM(ENTRADA!S14:S16)/SUM(ENTRADA!S11:S13)-1 -> -0.0068067727 | C16: =SUM(ENTRADA!T14:T16)/SUM(ENTRADA!T11:T13)-1 -> -0.021614971 | D16: =SUM(ENTRADA!U14:U16)/SUM(ENTRADA!U11:U13)-1 -> -0.0055596667 | E16: =SUM(ENTRADA!V14:V16)/SUM(ENTRADA!V11:V13)-1 -> -0.0033912762 | F16: =SUM(ENTRADA!W14:W16)/SUM(ENTRADA!W11:W13)-1 -> -0.014410018 | G16: =SUM(ENTRADA!X14:X16)/SUM(ENTRADA!X11:X13)-1 -> 0.00026049285 | J16: =SUM(ENTRADA!AA14:AA16)/SUM(ENTRADA!AA11:AA13)-1 -> #DIV/0! | K16: =SUM(ENTRADA!AB14:AB16)/SUM(ENTRADA!AB11:AB13)-1 -> #DIV/0! | L16: =SUM(ENTRADA!AC14:AC16)/SUM(ENTRADA!AC11:AC13)-1 -> #DIV/0! | M16: =SUM(ENTRADA!AD14:AD16)/SUM(ENTRADA!AD11:AD13)-1 -> #DIV/0! | N16: =SUM(ENTRADA!AE14:AE16)/SUM(ENTRADA!AE11:AE13)-1 -> -0.0059042203 | O16: =SUM(ENTRADA!AF14:AF16)/SUM(ENTRADA!AF11:AF13)-1 -> #DIV/0! | P16: =SUM(ENTRADA!AH14:AH16)/SUM(ENTRADA!AH11:AH13)-1 -> #REF!
A17: =ENTRADA!A17 -> 36861 | B17: =SUM(ENTRADA!S15:S17)/SUM(ENTRADA!S12:S14)-1 -> -0.0039899434 | C17: =SUM(ENTRADA!T15:T17)/SUM(ENTRADA!T12:T14)-1 -> -0.0040442561 | D17: =SUM(ENTRADA!U15:U17)/SUM(ENTRADA!U12:U14)-1 -> -0.0030478689 | E17: =SUM(ENTRADA!V15:V17)/SUM(ENTRADA!V12:V14)-1 -> -0.0019987241 | F17: =SUM(ENTRADA!W15:W17)/SUM(ENTRADA!W12:W14)-1 -> -0.018141641 | G17: =SUM(ENTRADA!X15:X17)/SUM(ENTRADA!X12:X14)-1 -> -0.0065938295 | J17: =SUM(ENTRADA!AA15:AA17)/SUM(ENTRADA!AA12:AA14)-1 -> #DIV/0! | K17: =SUM(ENTRADA!AB15:AB17)/SUM(ENTRADA!AB12:AB14)-1 -> #DIV/0! | L17: =SUM(ENTRADA!AC15:AC17)/SUM(ENTRADA!AC12:AC14)-1 -> #DIV/0! | M17: =SUM(ENTRADA!AD15:AD17)/SUM(ENTRADA!AD12:AD14)-1 -> #DIV/0! | N17: =SUM(ENTRADA!AE15:AE17)/SUM(ENTRADA!AE12:AE14)-1 -> 0.011012507 | O17: =SUM(ENTRADA!AF15:AF17)/SUM(ENTRADA!AF12:AF14)-1 -> #DIV/0! | P17: =SUM(ENTRADA!AH15:AH17)/SUM(ENTRADA!AH12:AH14)-1 -> #REF!
... A302: =ENTRADA!A302 -> 45536 | B302: =SUM(ENTRADA!S300:S302)/SUM(ENTRADA!S297:S299)-1 -> 0.0027692805 | C302: =SUM(ENTRADA!T300:T302)/SUM(ENTRADA!T297:T299)-1 -> -0.010545386 | D302: =SUM(ENTRADA!U300:U302)/SUM(ENTRADA!U297:U299)-1 -> 0.007375581 | E302: =SUM(ENTRADA!V300:V302)/SUM(ENTRADA!V297:V299)-1 -> 0.010756093 | F302: =SUM(ENTRADA!W300:W302)/SUM(ENTRADA!W297:W299)-1 -> 0.013191016 | G302: =SUM(ENTRADA!X300:X302)/SUM(ENTRADA!X297:X299)-1 -> 0.0037687558 | J302: =SUM(ENTRADA!AA300:AA302)/SUM(ENTRADA!AA297:AA299)-1 -> 0.016733144 | K302: =SUM(ENTRADA!AB300:AB302)/SUM(ENTRADA!AB297:AB299)-1 -> -0.027684492 | L302: =SUM(ENTRADA!AC300:AC302)/SUM(ENTRADA!AC297:AC299)-1 -> -0.021078629 | M302: =SUM(ENTRADA!AD300:AD302)/SUM(ENTRADA!AD297:AD299)-1 -> -0.013980571 | N302: =SUM(ENTRADA!AE300:AE302)/SUM(ENTRADA!AE297:AE299)-1 -> 0.043602515 | O302: =SUM(ENTRADA!AF300:AF302)/SUM(ENTRADA!AF297:AF299)-1 -> 0.030365949 | P302: =SUM(ENTRADA!AH300:AH302)/SUM(ENTRADA!AH297:AH299)-1 -> 0.0079190298

Sheet YoY
B1: VOLUME DE VENDAS NO VAREJO - BRASIL (Base: MÉDIA 2011=100)
B3: DADOS ORIGINAIS
A4: Período | B4: Comércio Varejista | C4: 1. Combustiveis e Lubrificantes | D4: 2. Hipermercados, supermercados, prod. alimenticios, bebidas e fumo | F4: 3. Tecidos, vestuario e calçados | G4: 4. Móveis e Eletrodomésticos | H4: Móveis | I4: Eletrodomésticos | J4: 5. Demais artigos de uso pessoal e doméstico | N4: 6. Veículos, motos, partes e peças | O4: 7. Material de Construção | P4: 8. Atacado especializado em produtos alimenticios, bebidas e fumo | Q4: Comércio Varejista Ampliado | T4: Comércio Varejista | U4: 1. Combustiveis e Lubrificantes | V4: 2. Hipermercados, supermercados, prod. alimenticios, bebidas e fumo | X4: 3. Tecidos, vestuario e calçados | Y4: 4. Móveis e Eletrodomésticos | Z4: Móveis | AA4: Eletrodomésticos | AB4: 5. Demais artigos de uso pessoal e doméstico | AF4: 6. Veículos, motos, partes e peças | AG4: 7. Material de Construção | AH4: 11. Atacado especializado em produtos alimenticios, bebidas e fumo | AI4: Comércio Varejista Ampliado
D5: Total | E5: 2.1 Supermercados e Hipermercados | J5: Artigos farmaceuticos, médicos, ortopédicos, de perfumaria e cosméticos | K5: Livros Jornais, revistas e papelaria | L5: Equipamentos e materiais para escritório, informática e comunicação | M5: Outros artigos de uso pessoal e domésticos | V5: Total | W5: 2.1 Supermercados e Hipermercados | AB5: Artigos farmaceuticos, médicos, ortopédicos, de perfumaria e cosméticos | AC5: Livros Jornais, revistas e papelaria | AD5: Equipamentos e materiais para escritório, informática e comunicação | AE5: Outros artigos de uso pessoal e domésticos
A6: =ENTRADA!A6 -> 36526 | B6: =ENTRADA!B6/ENTRADA!#REF!-1 -> #REF! | C6: =ENTRADA!C6/ENTRADA!#REF!-1 -> #REF! | D6: =ENTRADA!D6/ENTRADA!#REF!-1 -> #REF! | E6: =ENTRADA!E6/ENTRADA!#REF!-1 -> #REF! | F6: =ENTRADA!F6/ENTRADA!#REF!-1 -> #REF! | G6: =ENTRADA!G6/ENTRADA!#REF!-1 -> #REF! | H6: =ENTRADA!H6/ENTRADA!#REF!-1 -> #VALUE! | I6: =ENTRADA!I6/ENTRADA!#REF!-1 -> #VALUE! | ... Q6: =ENTRADA!Q6/ENTRADA!#REF!-1 -> #REF! | T6: =AVERAGE(B4:B6) -> #REF! | U6: =AVERAGE(C4:C6) -> #REF! | V6: =AVERAGE(D4:D6) -> #REF! | W6: =AVERAGE(E4:E6) -> #REF! | X6: =AVERAGE(F4:F6) -> #REF! | Y6: =AVERAGE(G4:G6) -> #REF! | Z6: =AVERAGE(H4:H6) -> #VALUE! | AA6: =AVERAGE(I4:I6) -> #VALUE! | ... AI6: =AVERAGE(Q4:Q6) -> #REF!
A7: =ENTRADA!A7 -> 36557 | B7: =ENTRADA!B7/ENTRADA!#REF!-1 -> #REF! | C7: =ENTRADA!C7/ENTRADA!#REF!-1 -> #REF! | D7: =ENTRADA!D7/ENTRADA!#REF!-1 -> #REF! | E7: =ENTRADA!E7/ENTRADA!#REF!-1 -> #REF! | F7: =ENTRADA!F7/ENTRADA!#REF!-1 -> #REF! | G7: =ENTRADA!G7/ENTRADA!#REF!-1 -> #REF! | H7: =ENTRADA!H7/ENTRADA!#REF!-1 -> #VALUE! | I7: =ENTRADA!I7/ENTRADA!#REF!-1 -> #VALUE! | ... Q7: =ENTRADA!Q7/ENTRADA!#REF!-1 -> #REF! | T7: =AVERAGE(B5:B7) -> #REF! | U7: =AVERAGE(C5:C7) -> #REF! | V7: =AVERAGE(D5:D7) -> #REF! | W7: =AVERAGE(E5:E7) -> #REF! | X7: =AVERAGE(F5:F7) -> #REF! | Y7: =AVERAGE(G5:G7) -> #REF! | Z7: =AVERAGE(H5:H7) -> #VALUE! | AA7: =AVERAGE(I5:I7) -> #VALUE! | ... AI7: =AVERAGE(Q5:Q7) -> #REF!
A8: =ENTRADA!A8 -> 36586 | B8: =ENTRADA!B8/ENTRADA!#REF!-1 -> #REF! | C8: =ENTRADA!C8/ENTRADA!#REF!-1 -> #REF! | D8: =ENTRADA!D8/ENTRADA!#REF!-1 -> #REF! | E8: =ENTRADA!E8/ENTRADA!#REF!-1 -> #REF! | F8: =ENTRADA!F8/ENTRADA!#REF!-1 -> #REF! | G8: =ENTRADA!G8/ENTRADA!#REF!-1 -> #REF! | H8: =ENTRADA!H8/ENTRADA!#REF!-1 -> #VALUE! | I8: =ENTRADA!I8/ENTRADA!#REF!-1 -> #VALUE! | ... Q8: =ENTRADA!Q8/ENTRADA!#REF!-1 -> #REF! | T8: =AVERAGE(B6:B8) -> #REF! | U8: =AVERAGE(C6:C8) -> #REF! | V8: =AVERAGE(D6:D8) -> #REF! | W8: =AVERAGE(E6:E8) -> #REF! | X8: =AVERAGE(F6:F8) -> #REF! | Y8: =AVERAGE(G6:G8) -> #REF! | Z8: =AVERAGE(H6:H8) -> #VALUE! | AA8: =AVERAGE(I6:I8) -> #VALUE! | ... AI8: =AVERAGE(Q6:Q8) -> #REF!
A9: =ENTRADA!A9 -> 36617 | B9: =ENTRADA!B9/ENTRADA!#REF!-1 -> #REF! | C9: =ENTRADA!C9/ENTRADA!#REF!-1 -> #REF! | D9: =ENTRADA!D9/ENTRADA!#REF!-1 -> #REF! | E9: =ENTRADA!E9/ENTRADA!#REF!-1 -> #REF! | F9: =ENTRADA!F9/ENTRADA!#REF!-1 -> #REF! | G9: =ENTRADA!G9/ENTRADA!#REF!-1 -> #REF! | H9: =ENTRADA!H9/ENTRADA!#REF!-1 -> #VALUE! | I9: =ENTRADA!I9/ENTRADA!#REF!-1 -> #VALUE! | ... Q9: =ENTRADA!Q9/ENTRADA!#REF!-1 -> #REF! | T9: =AVERAGE(B7:B9) -> #REF! | U9: =AVERAGE(C7:C9) -> #REF! | V9: =AVERAGE(D7:D9) -> #REF! | W9: =AVERAGE(E7:E9) -> #REF! | X9: =AVERAGE(F7:F9) -> #REF! | Y9: =AVERAGE(G7:G9) -> #REF! | Z9: =AVERAGE(H7:H9) -> #VALUE! | AA9: =AVERAGE(I7:I9) -> #VALUE! | ... AI9: =AVERAGE(Q7:Q9) -> #REF!
A10: =ENTRADA!A10 -> 36647 | B10: =ENTRADA!B10/ENTRADA!#REF!-1 -> #REF! | C10: =ENTRADA!C10/ENTRADA!#REF!-1 -> #REF! | D10: =ENTRADA!D10/ENTRADA!#REF!-1 -> #REF! | E10: =ENTRADA!E10/ENTRADA!#REF!-1 -> #REF! | F10: =ENTRADA!F10/ENTRADA!#REF!-1 -> #REF! | G10: =ENTRADA!G10/ENTRADA!#REF!-1 -> #REF! | H10: =ENTRADA!H10/ENTRADA!#REF!-1 -> #VALUE! | I10: =ENTRADA!I10/ENTRADA!#REF!-1 -> #VALUE! | ... Q10: =ENTRADA!Q10/ENTRADA!#REF!-1 -> #REF! | T10: =AVERAGE(B8:B10) -> #REF! | U10: =AVERAGE(C8:C10) -> #REF! | V10: =AVERAGE(D8:D10) -> #REF! | W10: =AVERAGE(E8:E10) -> #REF! | X10: =AVERAGE(F8:F10) -> #REF! | Y10: =AVERAGE(G8:G10) -> #REF! | Z10: =AVERAGE(H8:H10) -> #VALUE! | AA10: =AVERAGE(I8:I10) -> #VALUE! | ... AI10: =AVERAGE(Q8:Q10) -> #REF!
A11: =ENTRADA!A11 -> 36678 | B11: =ENTRADA!B11/ENTRADA!#REF!-1 -> #REF! | C11: =ENTRADA!C11/ENTRADA!#REF!-1 -> #REF! | D11: =ENTRADA!D11/ENTRADA!#REF!-1 -> #REF! | E11: =ENTRADA!E11/ENTRADA!#REF!-1 -> #REF! | F11: =ENTRADA!F11/ENTRADA!#REF!-1 -> #REF! | G11: =ENTRADA!G11/ENTRADA!#REF!-1 -> #REF! | H11: =ENTRADA!H11/ENTRADA!#REF!-1 -> #VALUE! | I11: =ENTRADA!I11/ENTRADA!#REF!-1 -> #VALUE! | ... Q11: =ENTRADA!Q11/ENTRADA!#REF!-1 -> #REF! | T11: =AVERAGE(B9:B11) -> #REF! | U11: =AVERAGE(C9:C11) -> #REF! | V11: =AVERAGE(D9:D11) -> #REF! | W11: =AVERAGE(E9:E11) -> #REF! | X11: =AVERAGE(F9:F11) -> #REF! | Y11: =AVERAGE(G9:G11) -> #REF! | Z11: =AVERAGE(H9:H11) -> #VALUE! | AA11: =AVERAGE(I9:I11) -> #VALUE! | ... AI11: =AVERAGE(Q9:Q11) -> #REF!
A12: =ENTRADA!A12 -> 36708 | B12: =ENTRADA!B12/ENTRADA!#REF!-1 -> #REF! | C12: =ENTRADA!C12/ENTRADA!#REF!-1 -> #REF! | D12: =ENTRADA!D12/ENTRADA!#REF!-1 -> #REF! | E12: =ENTRADA!E12/ENTRADA!#REF!-1 -> #REF! | F12: =ENTRADA!F12/ENTRADA!#REF!-1 -> #REF! | G12: =ENTRADA!G12/ENTRADA!#REF!-1 -> #REF! | H12: =ENTRADA!H12/ENTRADA!#REF!-1 -> #VALUE! | I12: =ENTRADA!I12/ENTRADA!#REF!-1 -> #VALUE! | ... Q12: =ENTRADA!Q12/ENTRADA!#REF!-1 -> #REF! | T12: =AVERAGE(B10:B12) -> #REF! | U12: =AVERAGE(C10:C12) -> #REF! | V12: =AVERAGE(D10:D12) -> #REF! | W12: =AVERAGE(E10:E12) -> #REF! | X12: =AVERAGE(F10:F12) -> #REF! | Y12: =AVERAGE(G10:G12) -> #REF! | Z12: =AVERAGE(H10:H12) -> #VALUE! | AA12: =AVERAGE(I10:I12) -> #VALUE! | ... AI12: =AVERAGE(Q10:Q12) -> #REF!
A13: =ENTRADA!A13 -> 36739 | B13: =ENTRADA!B13/ENTRADA!B1-1 -> #VALUE! | C13: =ENTRADA!C13/ENTRADA!C1-1 -> #DIV/0! | D13: =ENTRADA!D13/ENTRADA!D1-1 -> #DIV/0! | E13: =ENTRADA!E13/ENTRADA!E1-1 -> #DIV/0! | F13: =ENTRADA!F13/ENTRADA!F1-1 -> #DIV/0! | G13: =ENTRADA!G13/ENTRADA!G1-1 -> #DIV/0! | H13: =ENTRADA!H13/ENTRADA!H1-1 -> #VALUE! | I13: =ENTRADA!I13/ENTRADA!I1-1 -> #VALUE! | ... Q13: =ENTRADA!Q13/ENTRADA!Q1-1 -> #REF! | T13: =AVERAGE(B11:B13) -> #REF! | U13: =AVERAGE(C11:C13) -> #REF! | V13: =AVERAGE(D11:D13) -> #REF! | W13: =AVERAGE(E11:E13) -> #REF! | X13: =AVERAGE(F11:F13) -> #REF! | Y13: =AVERAGE(G11:G13) -> #REF! | Z13: =AVERAGE(H11:H13) -> #VALUE! | AA13: =AVERAGE(I11:I13) -> #VALUE! | ... AI13: =AVERAGE(Q11:Q13) -> #REF!
A14: =ENTRADA!A14 -> 36770 | B14: =ENTRADA!B14/ENTRADA!B2-1 -> #DIV/0! | C14: =ENTRADA!C14/ENTRADA!C2-1 -> #DIV/0! | D14: =ENTRADA!D14/ENTRADA!D2-1 -> #DIV/0! | E14: =ENTRADA!E14/ENTRADA!E2-1 -> #DIV/0! | F14: =ENTRADA!F14/ENTRADA!F2-1 -> #DIV/0! | G14: =ENTRADA!G14/ENTRADA!G2-1 -> #DIV/0! | H14: =ENTRADA!H14/ENTRADA!H2-1 -> #VALUE! | I14: =ENTRADA!I14/ENTRADA!I2-1 -> #VALUE! | ... Q14: =ENTRADA!Q14/ENTRADA!Q2-1 -> #REF! | T14: =AVERAGE(B12:B14) -> #REF! | U14: =AVERAGE(C12:C14) -> #REF! | V14: =AVERAGE(D12:D14) -> #REF! | W14: =AVERAGE(E12:E14) -> #REF! | X14: =AVERAGE(F12:F14) -> #REF! | Y14: =AVERAGE(G12:G14) -> #REF! | Z14: =AVERAGE(H12:H14) -> #VALUE! | AA14: =AVERAGE(I12:I14) -> #VALUE! | ... AI14: =AVERAGE(Q12:Q14) -> #REF!
A15: =ENTRADA!A15 -> 36800 | B15: =ENTRADA!B15/ENTRADA!B3-1 -> #VALUE! | C15: =ENTRADA!C15/ENTRADA!C3-1 -> #DIV/0! | D15: =ENTRADA!D15/ENTRADA!D3-1 -> #DIV/0! | E15: =ENTRADA!E15/ENTRADA!E3-1 -> #DIV/0! | F15: =ENTRADA!F15/ENTRADA!F3-1 -> #DIV/0! | G15: =ENTRADA!G15/ENTRADA!G3-1 -> #DIV/0! | H15: =ENTRADA!H15/ENTRADA!H3-1 -> #VALUE! | I15: =ENTRADA!I15/ENTRADA!I3-1 -> #VALUE! | ... Q15: =ENTRADA!Q15/ENTRADA!Q3-1 -> #REF! | T15: =AVERAGE(B13:B15) -> #VALUE! | U15: =AVERAGE(C13:C15) -> #DIV/0! | V15: =AVERAGE(D13:D15) -> #DIV/0! | W15: =AVERAGE(E13:E15) -> #DIV/0! | X15: =AVERAGE(F13:F15) -> #DIV/0! | Y15: =AVERAGE(G13:G15) -> #DIV/0! | Z15: =AVERAGE(H13:H15) -> #VALUE! | AA15: =AVERAGE(I13:I15) -> #VALUE! | ... AI15: =AVERAGE(Q13:Q15) -> #REF!
A16: =ENTRADA!A16 -> 36831 | B16: =ENTRADA!B16/ENTRADA!B4-1 -> #VALUE! | C16: =ENTRADA!C16/ENTRADA!C4-1 -> #VALUE! | D16: =ENTRADA!D16/ENTRADA!D4-1 -> #VALUE! | E16: =ENTRADA!E16/ENTRADA!E4-1 -> #DIV/0! | F16: =ENTRADA!F16/ENTRADA!F4-1 -> #VALUE! | G16: =ENTRADA!G16/ENTRADA!G4-1 -> #VALUE! | H16: =ENTRADA!H16/ENTRADA!H4-1 -> #VALUE! | I16: =ENTRADA!I16/ENTRADA!I4-1 -> #VALUE! | ... Q16: =ENTRADA!Q16/ENTRADA!Q4-1 -> #REF! | T16: =AVERAGE(B14:B16) -> #DIV/0! | U16: =AVERAGE(C14:C16) -> #DIV/0! | V16: =AVERAGE(D14:D16) -> #DIV/0! | W16: =AVERAGE(E14:E16) -> #DIV/0! | X16: =AVERAGE(F14:F16) -> #DIV/0! | Y16: =AVERAGE(G14:G16) -> #DIV/0! | Z16: =AVERAGE(H14:H16) -> #VALUE! | AA16: =AVERAGE(I14:I16) -> #VALUE! | ... AI16: =AVERAGE(Q14:Q16) -> #REF!
A17: =ENTRADA!A17 -> 36861 | B17: =ENTRADA!B17/ENTRADA!B5-1 -> #DIV/0! | C17: =ENTRADA!C17/ENTRADA!C5-1 -> #DIV/0! | D17: =ENTRADA!D17/ENTRADA!D5-1 -> #VALUE! | E17: =ENTRADA!E17/ENTRADA!E5-1 -> #VALUE! | F17: =ENTRADA!F17/ENTRADA!F5-1 -> #DIV/0! | G17: =ENTRADA!G17/ENTRADA!G5-1 -> #VALUE! | H17: =ENTRADA!H17/ENTRADA!H5-1 -> #VALUE! | I17: =ENTRADA!I17/ENTRADA!I5-1 -> #VALUE! | ... Q17: =ENTRADA!Q17/ENTRADA!Q5-1 -> #REF! | T17: =AVERAGE(B15:B17) -> #VALUE! | U17: =AVERAGE(C15:C17) -> #DIV/0! | V17: =AVERAGE(D15:D17) -> #DIV/0! | W17: =AVERAGE(E15:E17) -> #DIV/0! | X17: =AVERAGE(F15:F17) -> #DIV/0! | Y17: =AVERAGE(G15:G17) -> #DIV/0! | Z17: =AVERAGE(H15:H17) -> #VALUE! | AA17: =AVERAGE(I15:I17) -> #VALUE! | ... AI17: =AVERAGE(Q15:Q17) -> #REF!
A18: =ENTRADA!A18 -> 36892 | B18: =ENTRADA!B18/ENTRADA!B6-1 -> 0.018797052 | C18: =ENTRADA!C18/ENTRADA!C6-1 -> -0.079569886 | D18: =ENTRADA!D18/ENTRADA!D6-1 -> 0.032894881 | E18: =ENTRADA!E18/ENTRADA!E6-1 -> 0.033222674 | F18: =ENTRADA!F18/ENTRADA!F6-1 -> 0.079999948 | G18: =ENTRADA!G18/ENTRADA!G6-1 -> 0.11186466 | H18: =ENTRADA!H18/ENTRADA!H6-1 -> #VALUE! | I18: =ENTRADA!I18/ENTRADA!I6-1 -> #VALUE! | ... Q18: =ENTRADA!Q18/ENTRADA!Q6-1 -> #REF! | T18: =AVERAGE(B16:B18) -> #VALUE! | U18: =AVERAGE(C16:C18) -> #VALUE! | V18: =AVERAGE(D16:D18) -> #VALUE! | W18: =AVERAGE(E16:E18) -> #DIV/0! | X18: =AVERAGE(F16:F18) -> #VALUE! | Y18: =AVERAGE(G16:G18) -> #VALUE! | Z18: =AVERAGE(H16:H18) -> #VALUE! | AA18: =AVERAGE(I16:I18) -> #VALUE! | ... AI18: =AVERAGE(Q16:Q18) -> #REF!
A19: =ENTRADA!A19 -> 36923 | B19: =ENTRADA!B19/ENTRADA!B7-1 -> -0.050185855 | C19: =ENTRADA!C19/ENTRADA!C7-1 -> -0.12197796 | D19: =ENTRADA!D19/ENTRADA!D7-1 -> 0.0066225457 | E19: =ENTRADA!E19/ENTRADA!E7-1 -> 0.015075274 | F19: =ENTRADA!F19/ENTRADA!F7-1 -> -0.0091407252 | G19: =ENTRADA!G19/ENTRADA!G7-1 -> -0.0070422677 | H19: =ENTRADA!H19/ENTRADA!H7-1 -> #VALUE! | I19: =ENTRADA!I19/ENTRADA!I7-1 -> #VALUE! | ... Q19: =ENTRADA!Q19/ENTRADA!Q7-1 -> #REF! | T19: =AVERAGE(B17:B19) -> #DIV/0! | U19: =AVERAGE(C17:C19) -> #DIV/0! | V19: =AVERAGE(D17:D19) -> #VALUE! | W19: =AVERAGE(E17:E19) -> #VALUE! | X19: =AVERAGE(F17:F19) -> #DIV/0! | Y19: =AVERAGE(G17:G19) -> #VALUE! | Z19: =AVERAGE(H17:H19) -> #VALUE! | AA19: =AVERAGE(I17:I19) -> #VALUE! | ... AI19: =AVERAGE(Q17:Q19) -> #REF!
A20: =ENTRADA!A20 -> 36951 | B20: =ENTRADA!B20/ENTRADA!B8-1 -> 0.024955393 | C20: =ENTRADA!C20/ENTRADA!C8-1 -> -0.058635431 | D20: =ENTRADA!D20/ENTRADA!D8-1 -> 0.048362011 | E20: =ENTRADA!E20/ENTRADA!E8-1 -> 0.051805296 | F20: =ENTRADA!F20/ENTRADA!F8-1 -> 0.071304411 | G20: =ENTRADA!G20/ENTRADA!G8-1 -> 0.10631221 | H20: =ENTRADA!H20/ENTRADA!H8-1 -> #VALUE! | I20: =ENTRADA!I20/ENTRADA!I8-1 -> #VALUE! | ... Q20: =ENTRADA!Q20/ENTRADA!Q8-1 -> #REF! | T20: =AVERAGE(B18:B20) -> -0.00214447 | U20: =AVERAGE(C18:C20) -> -0.086727759 | V20: =AVERAGE(D18:D20) -> 0.029293146 | W20: =AVERAGE(E18:E20) -> 0.033367748 | X20: =AVERAGE(F18:F20) -> 0.047387878 | Y20: =AVERAGE(G18:G20) -> 0.070378201 | Z20: =AVERAGE(H18:H20) -> #VALUE! | AA20: =AVERAGE(I18:I20) -> #VALUE! | ... AI20: =AVERAGE(Q18:Q20) -> #REF!
